Workbook

Sheet Rekap
A1: Rekap Budget per Cluster — ADW, Evantama, CCSI 2026
A3: ASUMSI (berlaku untuk semua sheet)
A4: Interest Bank (% × Dana Investor) | C4: 0.1 | D4: Template: 10%. Sheet RAB lama memakai 6% × biaya subcon.
A5: Retensi dihitung sebagai biaya & masuk Dana Investor? | C5: Ya | D5: Template: Ya. "Tidak" = retensi diperlakukan sbg piutang (tetap tampil sbg info).
A7: Project | B7: Cluster / Site | C7: Nilai Proyek | D7: Dana Investor | E7: Interest Bank | F7: Outflow | G7: Profit | H7: Margin
A8: ADW | B8: =ADW!B1 -> TOTAL ADW | C8: =ADW!C6 -> 716165700 | D8: =ADW!C7 -> 6.5816431e+08 | E8: =ADW!C11 -> 65816431 | F8: =ADW!C22 -> 7.2398074e+08 | G8: =ADW!C23 -> -7815037.4 | H8: =IF(C8=0,0,G8/C8) -> -0.010912331
A9: ADW | B9: =ADW!D1 -> Gempol Cirebon | C9: =ADW!E6 -> 44741500 | D9: =ADW!E7 -> 42057010 | E9: =ADW!E11 -> 4205701 | F9: =ADW!E22 -> 46262711 | G9: =ADW!E23 -> -1521211 | H9: =IF(C9=0,0,G9/C9) -> -0.034
A10: ADW | B10: =ADW!F1 -> Kelurahan Mekarwangi Cianjur | C10: =ADW!G6 -> 94550250 | D10: =ADW!G7 -> 88449545 | E10: =ADW!G11 -> 8844954.5 | F10: =ADW!G22 -> 97294500 | G10: =ADW!G23 -> -2744249.5 | H10: =IF(C10=0,0,G10/C10) -> -0.029024244
A11: ADW | B11: =ADW!H1 -> Batumpang Rw 5 & 6 Purwakarta | C11: =ADW!I6 -> 25079800 | D11: =ADW!I7 -> 23309164 | E11: =ADW!I11 -> 2330916.4 | F11: =ADW!I22 -> 25640080 | G11: =ADW!I23 -> -560280.4 | H11: =IF(C11=0,0,G11/C11) -> -0.022339907
A12: ADW | B12: =ADW!J1 -> Sub Feeder Kel. Mekarwangi Cianjur | C12: =ADW!K6 -> 11247650 | D12: =ADW!K7 -> 10505277 | E12: =ADW!K11 -> 1050527.7 | F12: =ADW!K22 -> 11555805 | G12: =ADW!K23 -> -308154.7 | H12: =IF(C12=0,0,G12/C12) -> -0.027397252
A13: ADW | B13: =ADW!L1 -> Sub Feeder Batumpang Rw 5 & 6 Purwakarta | C13: =ADW!M6 -> 17181250 | D13: =ADW!M7 -> 16215256 | E13: =ADW!M11 -> 1621525.6 | F13: =ADW!M22 -> 17836782 | G13: =ADW!M23 -> -655531.88 | H13: =IF(C13=0,0,G13/C13) -> -0.038153911
A14: ADW | B14: =ADW!N1 -> Distribusi - TEPAS RW 07 NGAWI | C14: =ADW!O6 -> 17894900 | D14: =ADW!O7 -> 15787828 | E14: =ADW!O11 -> 1578782.8 | F14: =ADW!O22 -> 17366611 | G14: =ADW!O23 -> 528289.2 | H14: =IF(C14=0,0,G14/C14) -> 0.029521774
A15: ADW | B15: =ADW!P1 -> Subfeeder - TEPAS RW 07 NGAWI | C15: =ADW!Q6 -> 11563600 | D15: =ADW!Q7 -> 10598148 | E15: =ADW!Q11 -> 1059814.8 | F15: =ADW!Q22 -> 11657963 | G15: =ADW!Q23 -> -94362.8 | H15: =IF(C15=0,0,G15/C15) -> -0.0081603307
A16: ADW | B16: =ADW!R1 -> Distribusi - TEPAS RW 06 NGAWI | C16: =ADW!S6 -> 20021000 | D16: =ADW!S7 -> 16740620 | E16: =ADW!S11 -> 1674062 | F16: =ADW!S22 -> 18414682 | G16: =ADW!S23 -> 1606318 | H16: =IF(C16=0,0,G16/C16) -> 0.080231657
A17: ADW | B17: =ADW!T1 -> Distribusi - TEPAS RW 05 NGAWI -REV | C17: =ADW!U6 -> 33655100 | D17: =ADW!U7 -> 29700522 | E17: =ADW!U11 -> 2970052.2 | F17: =ADW!U22 -> 32670574 | G17: =ADW!U23 -> 984525.8 | H17: =IF(C17=0,0,G17/C17) -> 0.029253391
A18: ADW | B18: =ADW!V1 -> Subfeeder - TEPAS RW 05 NGAWI | C18: =ADW!W6 -> 10727300 | D18: =ADW!W7 -> 9684714 | E18: =ADW!W11 -> 968471.4 | F18: =ADW!W22 -> 10653185 | G18: =ADW!W23 -> 74114.6 | H18: =IF(C18=0,0,G18/C18) -> 0.0069089706
A19: ADW | B19: =ADW!X1 -> KELURAHAN SUKAPERNA MAJALENGKA | C19: =ADW!Y6 -> 43362200 | D19: =ADW!Y7 -> 43776896 | E19: =ADW!Y11 -> 4377689.6 | F19: =ADW!Y22 -> 48154586 | G19: =ADW!Y23 -> -4792385.6 | H19: =IF(C19=0,0,G19/C19) -> -0.11051989
A20: ADW | B20: =ADW!Z1 -> SINDANG RW 07 MAJALENGKA | C20: =ADW!AA6 -> 18878200 | D20: =ADW!AA7 -> 17110804 | E20: =ADW!AA11 -> 1711080.4 | F20: =ADW!AA22 -> 18821884 | G20: =ADW!AA23 -> 56315.6 | H20: =IF(C20=0,0,G20/C20) -> 0.0029831022
A21: ADW | B21: =ADW!AB1 -> SINDANG RW 02 MAJALENGKA | C21: =ADW!AC6 -> 16318600 | D21: =ADW!AC7 -> 14919842 | E21: =ADW!AC11 -> 1491984.2 | F21: =ADW!AC22 -> 16411826 | G21: =ADW!AC23 -> -93226.2 | H21: =IF(C21=0,0,G21/C21) -> -0.0057128798
A22: ADW | B22: =ADW!AD1 -> SINDANG RW 01 MAJALENGKA | C22: =ADW!AE6 -> 18945600 | D22: =ADW!AE7 -> 17401208 | E22: =ADW!AE11 -> 1740120.8 | F22: =ADW!AE22 -> 19141329 | G22: =ADW!AE23 -> -195728.8 | H22: =IF(C22=0,0,G22/C22) -> -0.010331095
A23: ADW | B23: =ADW!AF1 -> PULLING DISTRIBUSI KELURAHAN GUNUNGTAWANG WONOSOBO | C23: =ADW!AG6 -> 19128450 | D23: =ADW!AG7 -> 18198609 | E23: =ADW!AG11 -> 1819860.9 | F23: =ADW!AG22 -> 20018470 | G23: =ADW!AG23 -> -890019.9 | H23: =IF(C23=0,0,G23/C23) -> -0.046528595
A24: ADW | B24: =ADW!AH1 -> PULLING SUBFEEDER KELURAHAN GUNUNGTAWANG WONOSOBO | C24: =ADW!AI6 -> 16581600 | D24: =ADW!AI7 -> 16121852 | E24: =ADW!AI11 -> 1612185.2 | F24: =ADW!AI22 -> 17734037 | G24: =ADW!AI23 -> -1152437.2 | H24: =IF(C24=0,0,G24/C24) -> -0.069500965
A25: ADW | B25: =ADW!AJ1 -> PULLING DISTRIBUSI DUSUN MANGUNSARI TEGALSARI BARAT PEMALANG | C25: =ADW!AK6 -> 34125800 | D25: =ADW!AK7 -> 30034494 | E25: =ADW!AK11 -> 3003449.4 | F25: =ADW!AK22 -> 33037943 | G25: =ADW!AK23 -> 1087856.6 | H25: =IF(C25=0,0,G25/C25) -> 0.031877834
A26: ADW | B26: =ADW!AL1 -> PULLING SUBFEEDER DUSUN MANGUNSARI TEGALSARI BARAT PEMALANG | C26: =ADW!AM6 -> 32275850 | D26: =ADW!AM7 -> 29151953 | E26: =ADW!AM11 -> 2915195.3 | F26: =ADW!AM22 -> 32067148 | G26: =ADW!AM23 -> 208701.7 | H26: =IF(C26=0,0,G26/C26) -> 0.0064661876
A27: ADW | B27: =ADW!AN1 -> WANASARI RW 01 SUBANG | C27: =ADW!AO6 -> 9440850 | D27: =ADW!AO7 -> 8652253 | E27: =ADW!AO11 -> 865225.3 | F27: =ADW!AO22 -> 9517478.3 | G27: =ADW!AO23 -> -76628.3 | H27: =IF(C27=0,0,G27/C27) -> -0.0081166738
A28: ADW | B28: =ADW!AP1 -> WANASARI RW 02 SUBANG | C28: =ADW!AQ6 -> 13949300 | D28: =ADW!AQ7 -> 12830646 | E28: =ADW!AQ11 -> 1283064.6 | F28: =ADW!AQ22 -> 14113711 | G28: =ADW!AQ23 -> -164410.6 | H28: =IF(C28=0,0,G28/C28) -> -0.011786298
A29: ADW | B29: =ADW!AR1 -> WANASARI RW 03 SUBANG | C29: =ADW!AS6 -> 13447100 | D29: =ADW!AS7 -> 11873228 | E29: =ADW!AS11 -> 1187322.8 | F29: =ADW!AS22 -> 13060551 | G29: =ADW!AS23 -> 386549.2 | H29: =IF(C29=0,0,G29/C29) -> 0.028745915
A30: ADW | B30: =ADW!AT1 -> SF DESA WANASARI SUBANG | C30: =ADW!AU6 -> 42102050 | D30: =ADW!AU7 -> 38000419 | E30: =ADW!AU11 -> 3800041.9 | F30: =ADW!AU22 -> 41800461 | G30: =ADW!AU23 -> 301589.1 | H30: =IF(C30=0,0,G30/C30) -> 0.0071632878
A31: ADW | B31: =ADW!AV1 -> SARIREJA RW 01 SUBANG | C31: =ADW!AW6 -> 18179400 | D31: =ADW!AW7 -> 16543254 | E31: =ADW!AW11 -> 1654325.4 | F31: =ADW!AW22 -> 18197579 | G31: =ADW!AW23 -> -18179.4 | H31: =IF(C31=0,0,G31/C31) -> -0.001
A32: ADW | B32: =ADW!AX1 -> Distribusi Kel Karangmulyo | C32: =ADW!AY6 -> 54444550 | D32: =ADW!AY7 -> 50585169 | E32: =ADW!AY11 -> 5058516.9 | F32: =ADW!AY22 -> 55643686 | G32: =ADW!AY23 -> -1199135.9 | H32: =IF(C32=0,0,G32/C32) -> -0.022024902
A33: ADW | B33: =ADW!AZ1 -> Subfeeder Kel Karangmulyo | C33: =ADW!BA6 -> 14270900 | D33: =ADW!BA7 -> 13237362 | E33: =ADW!BA11 -> 1323736.2 | F33: =ADW!BA22 -> 14561098 | G33: =ADW!BA23 -> -290198.2 | H33: =IF(C33=0,0,G33/C33) -> -0.020334961
A34: ADW | B34: =ADW!BB1 -> PULLING DISTRIBUSI KELURAHAN TEGALAREN PURWOREJ | C34: =ADW!BC6 -> 22049500 | D34: =ADW!BC7 -> 20000690 | E34: =ADW!BC11 -> 2000069 | F34: =ADW!BC22 -> 22000759 | G34: =ADW!BC23 -> 48741 | H34: =IF(C34=0,0,G34/C34) -> 0.0022105263
A35: ADW | B35: =ADW!BD1 -> Distribusi Kel Tegalaren | C35: =ADW!BE6 -> 777050 | D35: =ADW!BE7 -> 500451 | E35: =ADW!BE11 -> 50045.1 | F35: =ADW!BE22 -> 550496.1 | G35: =ADW!BE23 -> 226553.9 | H35: =IF(C35=0,0,G35/C35) -> 0.2915564
A36: ADW | B36: =ADW!BF1 -> PULLING DISTRIBUSI KELURAHAN WINGKOHARJO PURWOREJO | C36: =ADW!BG6 -> 19543250 | D36: =ADW!BG7 -> 17369185 | E36: =ADW!BG11 -> 1736918.5 | F36: =ADW!BG22 -> 19106104 | G36: =ADW!BG23 -> 437146.5 | H36: =IF(C36=0,0,G36/C36) -> 0.022368158
A37: ADW | B37: =ADW!BH1 -> PULLING SUBFEEDER KELURAHAN WINGKOHARJO PURWOREJO | C37: =ADW!BI6 -> 13928900 | D37: =ADW!BI7 -> 11751586 | E37: =ADW!BI11 -> 1175158.6 | F37: =ADW!BI22 -> 12926744 | G37: =ADW!BI23 -> 1002155.9 | H37: =IF(C37=0,0,G37/C37) -> 0.071947961
A38: ADW | B38: =ADW!BJ1 -> SF SARIREJA RW 01 SUBANG | C38: =ADW!BK6 -> 7754200 | D38: =ADW!BK7 -> 7056322 | E38: =ADW!BK11 -> 705632.2 | F38: =ADW!BK22 -> 7761954.2 | G38: =ADW!BK23 -> -7754.2 | H38: =IF(C38=0,0,G38/C38) -> -0.001
A40: EVANTAMA | B40: =EVANTAMA!B1 -> TOTAL EVANTAMA | C40: =EVANTAMA!C6 -> 236454823 | D40: =EVANTAMA!C7 -> 2.2655812e+08 | E40: =EVANTAMA!C11 -> 22655812 | F40: =EVANTAMA!C22 -> 2.4921393e+08 | G40: =EVANTAMA!C23 -> -12759106 | H40: =IF(C40=0,0,G40/C40) -> -0.053960018
A41: EVANTAMA | B41: =EVANTAMA!D1 -> Cluster Sinagar Tasik | C41: =EVANTAMA!E6 -> 145940677 | D41: =EVANTAMA!E7 -> 1.3936208e+08 | E41: =EVANTAMA!E11 -> 13936208 | F41: =EVANTAMA!E22 -> 1.5329829e+08 | G41: =EVANTAMA!E23 -> -7357614.9 | H41: =IF(C41=0,0,G41/C41) -> -0.050415107
A42: EVANTAMA | B42: =EVANTAMA!F1 -> Cluster Kersanagara RW 08 Tasik | C42: =EVANTAMA!G6 -> 43882758 | D42: =EVANTAMA!G7 -> 43366385 | E42: =EVANTAMA!G11 -> 4336638.5 | F42: =EVANTAMA!G22 -> 47703023 | G42: =EVANTAMA!G23 -> -3820265.2 | H42: =IF(C42=0,0,G42/C42) -> -0.087056178
A43: EVANTAMA | B43: =EVANTAMA!H1 -> Cluster Kersanagara RW 04 Tasik | C43: =EVANTAMA!I6 -> 46631388 | D43: =EVANTAMA!I7 -> 43829649 | E43: =EVANTAMA!I11 -> 4382964.9 | F43: =EVANTAMA!I22 -> 48212614 | G43: =EVANTAMA!I23 -> -1581226.3 | H43: =IF(C43=0,0,G43/C43) -> -0.033909055
...

Sheet ADW
A1: Proyeksi Project ADW 2026 | B1: TOTAL ADW | D1: Gempol Cirebon | F1: Kelurahan Mekarwangi Cianjur | H1: Batumpang Rw 5 & 6 Purwakarta | J1: Sub Feeder Kel. Mekarwangi Cianjur | L1: Sub Feeder Batumpang Rw 5 & 6 Purwakarta | N1: Distribusi - TEPAS RW 07 NGAWI | P1: Subfeeder - TEPAS RW 07 NGAWI | R1: Distribusi - TEPAS RW 06 NGAWI | T1: Distribusi - TEPAS RW 05 NGAWI -REV | V1: Subfeeder - TEPAS RW 05 NGAWI | X1: KELURAHAN SUKAPERNA MAJALENGKA | Z1: SINDANG RW 07 MAJALENGKA | AB1: SINDANG RW 02 MAJALENGKA | AD1: SINDANG RW 01 MAJALENGKA | AF1: PULLING DISTRIBUSI KELURAHAN GUNUNGTAWANG WONOSOBO | AH1: PULLING SUBFEEDER KELURAHAN GUNUNGTAWANG WONOSOBO | AJ1: PULLING DISTRIBUSI DUSUN MANGUNSARI TEGALSARI BARAT PEMALANG | AL1: PULLING SUBFEEDER DUSUN MANGUNSARI TEGALSARI BARAT PEMALANG | AN1: WANASARI RW 01 SUBANG | AP1: WANASARI RW 02 SUBANG | AR1: WANASARI RW 03 SUBANG | AT1: SF DESA WANASARI SUBANG | AV1: SARIREJA RW 01 SUBANG | AX1: Distribusi Kel Karangmulyo | AZ1: Subfeeder Kel Karangmulyo | BB1: PULLING DISTRIBUSI KELURAHAN TEGALAREN PURWOREJ | BD1: Distribusi Kel Tegalaren | BF1: PULLING DISTRIBUSI KELURAHAN WINGKOHARJO PURWOREJO | BH1: PULLING SUBFEEDER KELURAHAN WINGKOHARJO PURWOREJO | BJ1: SF SARIREJA RW 01 SUBANG
D2: Divisi IBK · PO: PO/2026/07774 · Implementasi: 25/05/2026 | F2: Divisi IBK · SPK: 01 · PO: PO/2026/09495 · Implementasi: 20/07/2026 | H2: Divisi IBK · SPK: 02 · PO: PO/2026/094999 · Implementasi: 22/07/2026 | J2: Divisi IBK · SPK: 04 · Implementasi: 27/07/2026 | L2: Divisi IBK · SPK: 03 · PO: PO/2026/07774 · Implementasi: 28/07/2026 | N2: Divisi TELCO · SPK:01 · PO/2026/09244 · Implementasi : 07/08/2026 | P2: Divisi TELCO · SPK : 02 · PO/2026/09243 · Implementasi : 07/08/2026 | R2: Divisi TELCO · SPK : 03 · Implementasi : 07/08/2026 | T2: Divisi TELCO · SPK : 04 · PO/2026/09245 · Implementasi : 07/08/2026 | V2: Divisi TELCO · SPK : 05 · PO/2026/09247 · Implementasi : 07/08/2026 | X2: Divisi TELCO · SPK : 10 | Z2: Divisi TELCO · SPK : 09 · PO : PO/2026/09478 | AB2: Divisi TELCO · SPK : 06 · PO/2026/09471 | AD2: Divisi TELCO · SPK : 05 · PO/2026/09475 | AF2: Divisi TELCO · SPK : 01 | AH2: Divisi TELCO · SPK : 02 | AJ2: Divisi TELCO · SPK : 03 | AL2: Divisi TELCO · SPK : 04 | AN2: Divisi TELCO · SPK : 11 · PO/2026/09476 · Implementasi : 22/8/2026 | AP2: Divisi TELCO · SPK : 12 · PO/2026/09493 · Implementasi : 22/8/2026 | AR2: Divisi TELCO · SPK : 13 · PO/2026/09487 · Implementasi : 22/8/2026 | AT2: Divisi TELCO · SPK : 14 · PO/2026/09483 · Implementasi : 22/08/2026 | AV2: Divisi TELCO · SPK : 15 · PO/2026/09479 · Implementasi : 22/08/2026 | AX2: Divisi TELCO · SPK 07 · Implementasi : 16/09/2026 | AZ2: Divisi TELCO · SPK 08 · Implementasi : 16/09/2026 | BB2: Divisi TELCO · SPK 05 · Implementasi : 16/09/2026 | BD2: Divisi TELCO · SPK 06 · Implementasi : 16/09/2026 | BF2: Divisi TELCO · SPK : 09 · Implementasi : 28/09/2026 | BH2: Divisi TELCO · SPK : 10 · Implementasi : 28/09/2026 | BJ2: Divisi TELCO · SPK : 16 · PO/2026/09476
B3: % | C3: Rp | D3: % | E3: Rp | F3: % | G3: Rp | H3: % | I3: Rp | J3: % | K3: Rp | L3: % | M3: Rp | N3: % | O3: Rp | P3: % | Q3: Rp | R3: % | S3: Rp | T3: % | U3: Rp | V3: % | W3: Rp | X3: % | Y3: Rp | Z3: % | AA3: Rp | AB3: % | AC3: Rp | AD3: % | AE3: Rp | AF3: % | AG3: Rp | AH3: % | AI3: Rp | AJ3: % | AK3: Rp | AL3: % | AM3: Rp | AN3: % | AO3: Rp | AP3: % | AQ3: Rp | AR3: % | AS3: Rp | AT3: % | AU3: Rp | AV3: % | AW3: Rp | AX3: % | AY3: Rp | AZ3: % | BA3: Rp | BB3: % | BC3: Rp | BD3: % | BE3: Rp | BF3: % | BG3: Rp | BH3: % | BI3: Rp | BJ3: % | BK3: Rp
A4: Nilai PO Implementasi | C4: =SUMIF($D$3:$BK$3,"Rp",$D4:$BK4) -> 716165700 | E4: 44741500 | G4: 94550250 | I4: 25079800 | K4: 11247650 | M4: 17181250 | O4: 17894900 | Q4: 11563600 | S4: 20021000 | U4: 33655100 | W4: 10727300 | Y4: 43362200 | AA4: 18878200 | AC4: 16318600 | AE4: 18945600 | AG4: 19128450 | AI4: 16581600 | AK4: 34125800 | AM4: 32275850 | AO4: 9440850 | AQ4: 13949300 | AS4: 13447100 | AU4: 42102050 | AW4: 18179400 | AY4: 54444550 | BA4: 14270900 | BC4: 22049500 | BE4: 777050 | BG4: 19543250 | BI4: 13928900 | BK4: 7754200
A5: Nilai PO Permit | C5: =SUMIF($D$3:$BK$3,"Rp",$D5:$BK5) -> 0 | E5: 0 | G5: 0 | I5: 0 | K5: 0 | M5: 0 | O5: 0 | Q5: 0 | S5: 0 | U5: 0 | W5: 0 | Y5: 0 | AA5: 0 | AC5: 0 | AE5: 0 | AG5: 0 | AI5: 0 | AK5: 0 | AM5: 0 | AO5: 0 | AQ5: 0 | AS5: 0 | AU5: 0 | AW5: 0 | AY5: 0 | BA5: 0 | BC5: 0 | BE5: 0 | BG5: 0 | BI5: 0 | BK5: 0
A6: Nilai Proyek | C6: =SUMIF($D$3:$BK$3,"Rp",$D6:$BK6) -> 716165700 | E6: =E4+E5 -> 44741500 | G6: =G4+G5 -> 94550250 | I6: =I4+I5 -> 25079800 | K6: =K4+K5 -> 11247650 | M6: =M4+M5 -> 17181250 | O6: =O4+O5 -> 17894900 | Q6: =Q4+Q5 -> 11563600 | S6: =S4+S5 -> 20021000 | U6: =U4+U5 -> 33655100 | W6: =W4+W5 -> 10727300 | Y6: =Y4+Y5 -> 43362200 | AA6: =AA4+AA5 -> 18878200 | AC6: =AC4+AC5 -> 16318600 | AE6: =AE4+AE5 -> 18945600 | AG6: =AG4+AG5 -> 19128450 | AI6: =AI4+AI5 -> 16581600 | AK6: =AK4+AK5 -> 34125800 | AM6: =AM4+AM5 -> 32275850 | AO6: =AO4+AO5 -> 9440850 | AQ6: =AQ4+AQ5 -> 13949300 | AS6: =AS4+AS5 -> 13447100 | AU6: =AU4+AU5 -> 42102050 | AW6: =AW4+AW5 -> 18179400 | AY6: =AY4+AY5 -> 54444550 | BA6: =BA4+BA5 -> 14270900 | BC6: =BC4+BC5 -> 22049500 | BE6: =BE4+BE5 -> 777050 | BG6: =BG4+BG5 -> 19543250 | BI6: =BI4+BI5 -> 13928900 | BK6: =BK4+BK5 -> 7754200
A7: DUIT INVESTOR | B7: =IF(C6=0,0,C7/C6) -> 0.91901121 | C7: =SUMIF($D$3:$BK$3,"Rp",$D7:$BK7) -> 6.5816431e+08 | D7: =IF(E6=0,0,E7/E6) -> 0.94 | E7: =E8+E9+E10+E12+IF(Rekap!$C$5="Ya",E13,0)+SUM(E15:E21) -> 42057010 | F7: =IF(G6=0,0,G7/G6) -> 0.93547659 | G7: =G8+G9+G10+G12+IF(Rekap!$C$5="Ya",G13,0)+SUM(G15:G21) -> 88449545 | H7: =IF(I6=0,0,I7/I6) -> 0.92939992 | I7: =I8+I9+I10+I12+IF(Rekap!$C$5="Ya",I13,0)+SUM(I15:I21) -> 23309164 | J7: =IF(K6=0,0,K7/K6) -> 0.9339975 | K7: =K8+K9+K10+K12+IF(Rekap!$C$5="Ya",K13,0)+SUM(K15:K21) -> 10505277 | L7: =IF(M6=0,0,M7/M6) -> 0.94377628 | M7: =M8+M9+M10+M12+IF(Rekap!$C$5="Ya",M13,0)+SUM(M15:M21) -> 16215256 | N7: =IF(O6=0,0,O7/O6) -> 0.88225293 | O7: =O8+O9+O10+O12+IF(Rekap!$C$5="Ya",O13,0)+SUM(O15:O21) -> 15787828 | P7: =IF(Q6=0,0,Q7/Q6) -> 0.91650939 | Q7: =Q8+Q9+Q10+Q12+IF(Rekap!$C$5="Ya",Q13,0)+SUM(Q15:Q21) -> 10598148 | R7: =IF(S6=0,0,S7/S6) -> 0.83615304 | S7: =S8+S9+S10+S12+IF(Rekap!$C$5="Ya",S13,0)+SUM(S15:S21) -> 16740620 | T7: =IF(U6=0,0,U7/U6) -> 0.88249692 | U7: =U8+U9+U10+U12+IF(Rekap!$C$5="Ya",U13,0)+SUM(U15:U21) -> 29700522 | V7: =IF(W6=0,0,W7/W6) -> 0.90281003 | W7: =W8+W9+W10+W12+IF(Rekap!$C$5="Ya",W13,0)+SUM(W15:W21) -> 9684714 | X7: =IF(Y6=0,0,Y7/Y6) -> 1.0095635 | Y7: =Y8+Y9+Y10+Y12+IF(Rekap!$C$5="Ya",Y13,0)+SUM(Y15:Y21) -> 43776896 | Z7: =IF(AA6=0,0,AA7/AA6) -> 0.906379 | AA7: =AA8+AA9+AA10+AA12+IF(Rekap!$C$5="Ya",AA13,0)+SUM(AA15:AA21) -> 17110804 | AB7: =IF(AC6=0,0,AC7/AC6) -> 0.91428444 | AC7: =AC8+AC9+AC10+AC12+IF(Rekap!$C$5="Ya",AC13,0)+SUM(AC15:AC21) -> 14919842 | AD7: =IF(AE6=0,0,AE7/AE6) -> 0.91848281 | AE7: =AE8+AE9+AE10+AE12+IF(Rekap!$C$5="Ya",AE13,0)+SUM(AE15:AE21) -> 17401208 | AF7: =IF(AG6=0,0,AG7/AG6) -> 0.95138963 | AG7: =AG8+AG9+AG10+AG12+IF(Rekap!$C$5="Ya",AG13,0)+SUM(AG15:AG21) -> 18198609 | AH7: =IF(AI6=0,0,AI7/AI6) -> 0.9722736 | AI7: =AI8+AI9+AI10+AI12+IF(Rekap!$C$5="Ya",AI13,0)+SUM(AI15:AI21) -> 16121852 | AJ7: =IF(AK6=0,0,AK7/AK6) -> 0.88011106 | AK7: =AK8+AK9+AK10+AK12+IF(Rekap!$C$5="Ya",AK13,0)+SUM(AK15:AK21) -> 30034494 | AL7: =IF(AM6=0,0,AM7/AM6) -> 0.90321256 | AM7: =AM8+AM9+AM10+AM12+IF(Rekap!$C$5="Ya",AM13,0)+SUM(AM15:AM21) -> 29151953 | AN7: =IF(AO6=0,0,AO7/AO6) -> 0.9164697 | AO7: =AO8+AO9+AO10+AO12+IF(Rekap!$C$5="Ya",AO13,0)+SUM(AO15:AO21) -> 8652253 | AP7: =IF(AQ6=0,0,AQ7/AQ6) -> 0.91980573 | AQ7: =AQ8+AQ9+AQ10+AQ12+IF(Rekap!$C$5="Ya",AQ13,0)+SUM(AQ15:AQ21) -> 12830646 | AR7: =IF(AS6=0,0,AS7/AS6) -> 0.88295826 | AS7: =AS8+AS9+AS10+AS12+IF(Rekap!$C$5="Ya",AS13,0)+SUM(AS15:AS21) -> 11873228 | AT7: =IF(AU6=0,0,AU7/AU6) -> 0.90257883 | AU7: =AU8+AU9+AU10+AU12+IF(Rekap!$C$5="Ya",AU13,0)+SUM(AU15:AU21) -> 38000419 | AV7: =IF(AW6=0,0,AW7/AW6) -> 0.91 | AW7: =AW8+AW9+AW10+AW12+IF(Rekap!$C$5="Ya",AW13,0)+SUM(AW15:AW21) -> 16543254 | AX7: =IF(AY6=0,0,AY7/AY6) -> 0.92911355 | AY7: =AY8+AY9+AY10+AY12+IF(Rekap!$C$5="Ya",AY13,0)+SUM(AY15:AY21) -> 50585169 | AZ7: =IF(BA6=0,0,BA7/BA6) -> 0.92757724 | BA7: =BA8+BA9+BA10+BA12+IF(Rekap!$C$5="Ya",BA13,0)+SUM(BA15:BA21) -> 13237362 | BB7: =IF(BC6=0,0,BC7/BC6) -> 0.90708134 | BC7: =BC8+BC9+BC10+BC12+IF(Rekap!$C$5="Ya",BC13,0)+SUM(BC15:BC21) -> 20000690 | BD7: =IF(BE6=0,0,BE7/BE6) -> 0.64403964 | BE7: =BE8+BE9+BE10+BE12+IF(Rekap!$C$5="Ya",BE13,0)+SUM(BE15:BE21) -> 500451 | BF7: =IF(BG6=0,0,BG7/BG6) -> 0.88875622 | BG7: =BG8+BG9+BG10+BG12+IF(Rekap!$C$5="Ya",BG13,0)+SUM(BG15:BG21) -> 17369185 | BH7: =IF(BI6=0,0,BI7/BI6) -> 0.84368367 | BI7: =BI8+BI9+BI10+BI12+IF(Rekap!$C$5="Ya",BI13,0)+SUM(BI15:BI21) -> 11751586 | BJ7: =IF(BK6=0,0,BK7/BK6) -> 0.91 | BK7: =BK8+BK9+BK10+BK12+IF(Rekap!$C$5="Ya",BK13,0)+SUM(BK15:BK21) -> 7056322
A8: Biaya Subcon | B8: =IF(C4=0,0,C8/C4) -> 0.72771882 | C8: =SUMIF($D$3:$BK$3,"Rp",$D8:$BK8) -> 5.2116726e+08 | D8: =IF(E$4=0,0,E8/E$4) -> 0.76 | E8: 34003540 | F8: =IF(G$4=0,0,G8/G$4) -> 0.75547659 | G8: 71430500 | H8: =IF(I$4=0,0,I8/I$4) -> 0.74939992 | I8: 18794800 | J8: =IF(K$4=0,0,K8/K$4) -> 0.7539975 | K8: 8480700 | L8: =IF(M$4=0,0,M8/M$4) -> 0.77077628 | M8: 13242900 | N8: =IF(O$4=0,0,O8/O$4) -> 0.66225293 | O8: 11850950 | P8: =IF(Q$4=0,0,Q8/Q$4) -> 0.73650939 | Q8: 8516700 | R8: =IF(S$4=0,0,S8/S$4) -> 0.61615304 | S8: 12336000 | T8: =IF(U$4=0,0,U8/U$4) -> 0.66249692 | U8: 22296400 | V8: =IF(W$4=0,0,W8/W$4) -> 0.72281003 | W8: 7753800 | X8: =IF(Y$4=0,0,Y8/Y$4) -> 0.82956354 | Y8: 35971700 | Z8: =IF(AA$4=0,0,AA8/AA$4) -> 0.686379 | AA8: 12957600 | AB8: =IF(AC$4=0,0,AC8/AC$4) -> 0.69428444 | AC8: 11329750 | AD8: =IF(AE$4=0,0,AE8/AE$4) -> 0.73848281 | AE8: 13991000 | AF8: =IF(AG$4=0,0,AG8/AG$4) -> 0.73138963 | AG8: 13990350 | AH8: =IF(AI$4=0,0,AI8/AI$4) -> 0.7522736 | AI8: 12473900 | AJ8: =IF(AK$4=0,0,AK8/AK$4) -> 0.70011106 | AK8: 23891850 | AL8: =IF(AM$4=0,0,AM8/AM$4) -> 0.72321256 | AM8: 23342300 | AN8: =IF(AO$4=0,0,AO8/AO$4) -> 0.7364697 | AO8: 6952900 | AP8: =IF(AQ$4=0,0,AQ8/AQ$4) -> 0.69980573 | AQ8: 9761800 | AR8: =IF(AS$4=0,0,AS8/AS$4) -> 0.70295826 | AS8: 9452750 | AT8: =IF(AU$4=0,0,AU8/AU$4) -> 0.72257883 | AU8: 30422050 | AV8: =IF(AW$4=0,0,AW8/AW$4) -> 0.69 | AW8: 12543786 | AX8: =IF(AY$4=0,0,AY8/AY$4) -> 0.74911355 | AY8: 40785150 | AZ8: =IF(BA$4=0,0,BA8/BA$4) -> 0.74757724 | BA8: 10668600 | BB8: =IF(BC$4=0,0,BC8/BC$4) -> 0.68708134 | BC8: 15149800 | BD8: =IF(BE$4=0,0,BE8/BE$4) -> 0.42403964 | BE8: 329500 | BF8: =IF(BG$4=0,0,BG8/BG$4) -> 0.70875622 | BG8: 13851400 | BH8: =IF(BI$4=0,0,BI8/BI$4) -> 0.66368367 | BI8: 9244383.5 | BJ8: =IF(BK$4=0,0,BK8/BK$4) -> 0.69 | BK8: 5350398
A9: Biaya Permit | B9: =IF(C4=0,0,C9/C4) -> 0 | C9: =SUMIF($D$3:$BK$3,"Rp",$D9:$BK9) -> 0 | D9: =IF(E$5=0,0,E9/E$5) -> 0 | E9: 0 | F9: =IF(G$5=0,0,G9/G$5) -> 0 | G9: 0 | H9: =IF(I$5=0,0,I9/I$5) -> 0 | I9: 0 | J9: =IF(K$5=0,0,K9/K$5) -> 0 | K9: 0 | L9: =IF(M$5=0,0,M9/M$5) -> 0 | M9: 0 | N9: =IF(O$5=0,0,O9/O$5) -> 0 | O9: 0 | P9: =IF(Q$5=0,0,Q9/Q$5) -> 0 | Q9: 0 | R9: =IF(S$5=0,0,S9/S$5) -> 0 | S9: 0 | T9: =IF(U$5=0,0,U9/U$5) -> 0 | U9: 0 | V9: =IF(W$5=0,0,W9/W$5) -> 0 | W9: 0 | X9: =IF(Y$5=0,0,Y9/Y$5) -> 0 | Y9: 0 | Z9: =IF(AA$5=0,0,AA9/AA$5) -> 0 | AA9: 0 | AB9: =IF(AC$5=0,0,AC9/AC$5) -> 0 | AC9: 0 | AD9: =IF(AE$5=0,0,AE9/AE$5) -> 0 | AE9: 0 | AF9: =IF(AG$5=0,0,AG9/AG$5) -> 0 | AG9: 0 | AH9: =IF(AI$5=0,0,AI9/AI$5) -> 0 | AI9: 0 | AJ9: =IF(AK$5=0,0,AK9/AK$5) -> 0 | AK9: 0 | AL9: =IF(AM$5=0,0,AM9/AM$5) -> 0 | AM9: 0 | AN9: =IF(AO$5=0,0,AO9/AO$5) -> 0 | AO9: 0 | AP9: =IF(AQ$5=0,0,AQ9/AQ$5) -> 0 | AQ9: 0 | AR9: =IF(AS$5=0,0,AS9/AS$5) -> 0 | AS9: 0 | AT9: =IF(AU$5=0,0,AU9/AU$5) -> 0 | AU9: 0 | AV9: =IF(AW$5=0,0,AW9/AW$5) -> 0 | AW9: 0 | AX9: =IF(AY$5=0,0,AY9/AY$5) -> 0 | AY9: 0 | AZ9: =IF(BA$5=0,0,BA9/BA$5) -> 0 | BA9: 0 | BB9: =IF(BC$5=0,0,BC9/BC$5) -> 0 | BC9: 0 | BD9: =IF(BE$5=0,0,BE9/BE$5) -> 0 | BE9: 0 | BF9: =IF(BG$5=0,0,BG9/BG$5) -> 0 | BG9: 0 | BH9: =IF(BI$5=0,0,BI9/BI$5) -> 0 | BI9: 0 | BJ9: =IF(BK$5=0,0,BK9/BK$5) -> 0 | BK9: 0
A10: Ticket Internal | B10: =IF(C4=0,0,C10/C4) -> 0 | C10: =SUMIF($D$3:$BK$3,"Rp",$D10:$BK10) -> 0 | D10: 0 | E10: =D10*E$4 -> 0 | F10: 0 | G10: =F10*G$4 -> 0 | H10: 0 | I10: =H10*I$4 -> 0 | J10: 0 | K10: =J10*K$4 -> 0 | L10: 0 | M10: =L10*M$4 -> 0 | N10: 0 | O10: =N10*O$4 -> 0 | P10: 0 | Q10: =P10*Q$4 -> 0 | R10: 0 | S10: =R10*S$4 -> 0 | T10: 0 | U10: =T10*U$4 -> 0 | V10: 0 | W10: =V10*W$4 -> 0 | X10: 0 | Y10: =X10*Y$4 -> 0 | Z10: 0 | AA10: =Z10*AA$4 -> 0 | AB10: 0 | AC10: =AB10*AC$4 -> 0 | AD10: 0 | AE10: =AD10*AE$4 -> 0 | AF10: 0 | AG10: =AF10*AG$4 -> 0 | AH10: 0 | AI10: =AH10*AI$4 -> 0 | AJ10: 0 | AK10: =AJ10*AK$4 -> 0 | AL10: 0 | AM10: =AL10*AM$4 -> 0 | AN10: 0 | AO10: =AN10*AO$4 -> 0 | AP10: 0 | AQ10: =AP10*AQ$4 -> 0 | AR10: 0 | AS10: =AR10*AS$4 -> 0 | AT10: 0 | AU10: =AT10*AU$4 -> 0 | AV10: 0 | AW10: =AV10*AW$4 -> 0 | AX10: 0 | AY10: =AX10*AY$4 -> 0 | AZ10: 0 | BA10: =AZ10*BA$4 -> 0 | BB10: 0 | BC10: =BB10*BC$4 -> 0 | BD10: 0 | BE10: =BD10*BE$4 -> 0 | BF10: 0 | BG10: =BF10*BG$4 -> 0 | BH10: 0 | BI10: =BH10*BI$4 -> 0 | BJ10: 0 | BK10: =BJ10*BK$4 -> 0
A11: Interest Bank | B11: =IF(C7=0,0,C11/C7) -> 0.1 | C11: =SUMIF($D$3:$BK$3,"Rp",$D11:$BK11) -> 65816431 | D11: =Rekap!$C$4 -> 0.1 | E11: =D11*E$7 -> 4205701 | F11: =Rekap!$C$4 -> 0.1 | G11: =F11*G$7 -> 8844954.5 | H11: =Rekap!$C$4 -> 0.1 | I11: =H11*I$7 -> 2330916.4 | J11: =Rekap!$C$4 -> 0.1 | K11: =J11*K$7 -> 1050527.7 | L11: =Rekap!$C$4 -> 0.1 | M11: =L11*M$7 -> 1621525.6 | N11: =Rekap!$C$4 -> 0.1 | O11: =N11*O$7 -> 1578782.8 | P11: =Rekap!$C$4 -> 0.1 | Q11: =P11*Q$7 -> 1059814.8 | R11: =Rekap!$C$4 -> 0.1 | S11: =R11*S$7 -> 1674062 | T11: =Rekap!$C$4 -> 0.1 | U11: =T11*U$7 -> 2970052.2 | V11: =Rekap!$C$4 -> 0.1 | W11: =V11*W$7 -> 968471.4 | X11: =Rekap!$C$4 -> 0.1 | Y11: =X11*Y$7 -> 4377689.6 | Z11: =Rekap!$C$4 -> 0.1 | AA11: =Z11*AA$7 -> 1711080.4 | AB11: =Rekap!$C$4 -> 0.1 | AC11: =AB11*AC$7 -> 1491984.2 | AD11: =Rekap!$C$4 -> 0.1 | AE11: =AD11*AE$7 -> 1740120.8 | AF11: =Rekap!$C$4 -> 0.1 | AG11: =AF11*AG$7 -> 1819860.9 | AH11: =Rekap!$C$4 -> 0.1 | AI11: =AH11*AI$7 -> 1612185.2 | AJ11: =Rekap!$C$4 -> 0.1 | AK11: =AJ11*AK$7 -> 3003449.4 | AL11: =Rekap!$C$4 -> 0.1 | AM11: =AL11*AM$7 -> 2915195.3 | AN11: =Rekap!$C$4 -> 0.1 | AO11: =AN11*AO$7 -> 865225.3 | AP11: =Rekap!$C$4 -> 0.1 | AQ11: =AP11*AQ$7 -> 1283064.6 | AR11: =Rekap!$C$4 -> 0.1 | AS11: =AR11*AS$7 -> 1187322.8 | AT11: =Rekap!$C$4 -> 0.1 | AU11: =AT11*AU$7 -> 3800041.9 | AV11: =Rekap!$C$4 -> 0.1 | AW11: =AV11*AW$7 -> 1654325.4 | AX11: =Rekap!$C$4 -> 0.1 | AY11: =AX11*AY$7 -> 5058516.9 | AZ11: =Rekap!$C$4 -> 0.1 | BA11: =AZ11*BA$7 -> 1323736.2 | BB11: =Rekap!$C$4 -> 0.1 | BC11: =BB11*BC$7 -> 2000069 | BD11: =Rekap!$C$4 -> 0.1 | BE11: =BD11*BE$7 -> 50045.1 | BF11: =Rekap!$C$4 -> 0.1 | BG11: =BF11*BG$7 -> 1736918.5 | BH11: =Rekap!$C$4 -> 0.1 | BI11: =BH11*BI$7 -> 1175158.6 | BJ11: =Rekap!$C$4 -> 0.1 | BK11: =BJ11*BK$7 -> 705632.2
A12: Pajak | B12: =IF(C6=0,0,C12/C6) -> 0.025 | C12: =SUMIF($D$3:$BK$3,"Rp",$D12:$BK12) -> 17904142 | D12: 0.025 | E12: =D12*E$6 -> 1118537.5 | F12: 0.025 | G12: =F12*G$6 -> 2363756.2 | H12: 0.025 | I12: =H12*I$6 -> 626995 | J12: 0.025 | K12: =J12*K$6 -> 281191.25 | L12: 0.025 | M12: =L12*M$6 -> 429531.25 | N12: 0.025 | O12: =N12*O$6 -> 447372.5 | P12: 0.025 | Q12: =P12*Q$6 -> 289090 | R12: 0.025 | S12: =R12*S$6 -> 500525 | T12: 0.025 | U12: =T12*U$6 -> 841377.5 | V12: 0.025 | W12: =V12*W$6 -> 268182.5 | X12: 0.025 | Y12: =X12*Y$6 -> 1084055 | Z12: 0.025 | AA12: =Z12*AA$6 -> 471955 | AB12: 0.025 | AC12: =AB12*AC$6 -> 407965 | AD12: 0.025 | AE12: =AD12*AE$6 -> 473640 | AF12: 0.025 | AG12: =AF12*AG$6 -> 478211.25 | AH12: 0.025 | AI12: =AH12*AI$6 -> 414540 | AJ12: 0.025 | AK12: =AJ12*AK$6 -> 853145 | AL12: 0.025 | AM12: =AL12*AM$6 -> 806896.25 | AN12: 0.025 | AO12: =AN12*AO$6 -> 236021.25 | AP12: 0.025 | AQ12: =AP12*AQ$6 -> 348732.5 | AR12: 0.025 | AS12: =AR12*AS$6 -> 336177.5 | AT12: 0.025 | AU12: =AT12*AU$6 -> 1052551.2 | AV12: 0.025 | AW12: =AV12*AW$6 -> 454485 | AX12: 0.025 | AY12: =AX12*AY$6 -> 1361113.8 | AZ12: 0.025 | BA12: =AZ12*BA$6 -> 356772.5 | BB12: 0.025 | BC12: =BB12*BC$6 -> 551237.5 | BD12: 0.025 | BE12: =BD12*BE$6 -> 19426.25 | BF12: 0.025 | BG12: =BF12*BG$6 -> 488581.25 | BH12: 0.025 | BI12: =BH12*BI$6 -> 348222.5 | BJ12: 0.025 | BK12: =BJ12*BK$6 -> 193855
A13: Retensi | B13: =IF(C4=0,0,C13/C4) -> 0.1 | C13: =SUMIF($D$3:$BK$3,"Rp",$D13:$BK13) -> 71616570 | D13: 0.1 | E13: =D13*E$4 -> 4474150 | F13: 0.1 | G13: =F13*G$4 -> 9455025 | H13: 0.1 | I13: =H13*I$4 -> 2507980 | J13: 0.1 | K13: =J13*K$4 -> 1124765 | L13: 0.1 | M13: =L13*M$4 -> 1718125 | N13: 0.1 | O13: =N13*O$4 -> 1789490 | P13: 0.1 | Q13: =P13*Q$4 -> 1156360 | R13: 0.1 | S13: =R13*S$4 -> 2002100 | T13: 0.1 | U13: =T13*U$4 -> 3365510 | V13: 0.1 | W13: =V13*W$4 -> 1072730 | X13: 0.1 | Y13: =X13*Y$4 -> 4336220 | Z13: 0.1 | AA13: =Z13*AA$4 -> 1887820 | AB13: 0.1 | AC13: =AB13*AC$4 -> 1631860 | AD13: 0.1 | AE13: =AD13*AE$4 -> 1894560 | AF13: 0.1 | AG13: =AF13*AG$4 -> 1912845 | AH13: 0.1 | AI13: =AH13*AI$4 -> 1658160 | AJ13: 0.1 | AK13: =AJ13*AK$4 -> 3412580 | AL13: 0.1 | AM13: =AL13*AM$4 -> 3227585 | AN13: 0.1 | AO13: =AN13*AO$4 -> 944085 | AP13: 0.1 | AQ13: =AP13*AQ$4 -> 1394930 | AR13: 0.1 | AS13: =AR13*AS$4 -> 1344710 | AT13: 0.1 | AU13: =AT13*AU$4 -> 4210205 | AV13: 0.1 | AW13: =AV13*AW$4 -> 1817940 | AX13: 0.1 | AY13: =AX13*AY$4 -> 5444455 | AZ13: 0.1 | BA13: =AZ13*BA$4 -> 1427090 | BB13: 0.1 | BC13: =BB13*BC$4 -> 2204950 | BD13: 0.1 | BE13: =BD13*BE$4 -> 77705 | BF13: 0.1 | BG13: =BF13*BG$4 -> 1954325 | BH13: 0.1 | BI13: =BH13*BI$4 -> 1392890 | BJ13: 0.1 | BK13: =BJ13*BK$4 -> 775420
A14: COST PROJECT
A15: Indirect Cost | B15: =IF(C4=0,0,C15/C4) -> 0.012865081 | C15: =SUMIF($D$3:$BK$3,"Rp",$D15:$BK15) -> 9213530 | D15: 0.01 | E15: =D15*E$4 -> 447415 | F15: 0.01 | G15: =F15*G$4 -> 945502.5 | H15: 0.01 | I15: =H15*I$4 -> 250798 | J15: 0.01 | K15: =J15*K$4 -> 112476.5 | L15: 0.01 | M15: =L15*M$4 -> 171812.5 | N15: 0.02 | O15: =N15*O$4 -> 357898 | P15: 0.01 | Q15: =P15*Q$4 -> 115636 | R15: 0.02 | S15: =R15*S$4 -> 400420 | T15: 0.02 | U15: =T15*U$4 -> 673102 | V15: 0.01 | W15: =V15*W$4 -> 107273 | X15: 0.01 | Y15: =X15*Y$4 -> 433622 | Z15: 0.02 | AA15: =Z15*AA$4 -> 377564 | AB15: 0.02 | AC15: =AB15*AC$4 -> 326372 | AD15: 0.01 | AE15: =AD15*AE$4 -> 189456 | AF15: 0.02 | AG15: =AF15*AG$4 -> 382569 | AH15: 0.02 | AI15: =AH15*AI$4 -> 331632 | AJ15: 0.01 | AK15: =AJ15*AK$4 -> 341258 | AL15: 0.01 | AM15: =AL15*AM$4 -> 322758.5 | AN15: 0.01 | AO15: =AN15*AO$4 -> 94408.5 | AP15: 0.02 | AQ15: =AP15*AQ$4 -> 278986 | AR15: 0.01 | AS15: =AR15*AS$4 -> 134471 | AT15: 0.01 | AU15: =AT15*AU$4 -> 421020.5 | AV15: 0.02 | AW15: =AV15*AW$4 -> 363588 | AX15: 0.01 | AY15: =AX15*AY$4 -> 544445.5 | AZ15: 0.01 | BA15: =AZ15*BA$4 -> 142709 | BB15: 0.02 | BC15: =BB15*BC$4 -> 440990 | BD15: 0.02 | BE15: =BD15*BE$4 -> 15541 | BF15: 0.01 | BG15: =BF15*BG$4 -> 195432.5 | BH15: 0.01 | BI15: =BH15*BI$4 -> 139289 | BJ15: 0.02 | BK15: =BJ15*BK$4 -> 155084
A16: Direct Cost | B16: =IF(C4=0,0,C16/C4) -> 0.019297622 | C16: =SUMIF($D$3:$BK$3,"Rp",$D16:$BK16) -> 13820295 | D16: 0.015 | E16: =D16*E$4 -> 671122.5 | F16: 0.015 | G16: =F16*G$4 -> 1418253.8 | H16: 0.015 | I16: =H16*I$4 -> 376197 | J16: 0.015 | K16: =J16*K$4 -> 168714.75 | L16: 0.015 | M16: =L16*M$4 -> 257718.75 | N16: 0.03 | O16: =N16*O$4 -> 536847 | P16: 0.015 | Q16: =P16*Q$4 -> 173454 | R16: 0.03 | S16: =R16*S$4 -> 600630 | T16: 0.03 | U16: =T16*U$4 -> 1009653 | V16: 0.015 | W16: =V16*W$4 -> 160909.5 | X16: 0.015 | Y16: =X16*Y$4 -> 650433 | Z16: 0.03 | AA16: =Z16*AA$4 -> 566346 | AB16: 0.03 | AC16: =AB16*AC$4 -> 489558 | AD16: 0.015 | AE16: =AD16*AE$4 -> 284184 | AF16: 0.03 | AG16: =AF16*AG$4 -> 573853.5 | AH16: 0.03 | AI16: =AH16*AI$4 -> 497448 | AJ16: 0.015 | AK16: =AJ16*AK$4 -> 511887 | AL16: 0.015 | AM16: =AL16*AM$4 -> 484137.75 | AN16: 0.015 | AO16: =AN16*AO$4 -> 141612.75 | AP16: 0.03 | AQ16: =AP16*AQ$4 -> 418479 | AR16: 0.015 | AS16: =AR16*AS$4 -> 201706.5 | AT16: 0.015 | AU16: =AT16*AU$4 -> 631530.75 | AV16: 0.03 | AW16: =AV16*AW$4 -> 545382 | AX16: 0.015 | AY16: =AX16*AY$4 -> 816668.25 | AZ16: 0.015 | BA16: =AZ16*BA$4 -> 214063.5 | BB16: 0.03 | BC16: =BB16*BC$4 -> 661485 | BD16: 0.03 | BE16: =BD16*BE$4 -> 23311.5 | BF16: 0.015 | BG16: =BF16*BG$4 -> 293148.75 | BH16: 0.015 | BI16: =BH16*BI$4 -> 208933.5 | BJ16: 0.03 | BK16: =BJ16*BK$4 -> 232626
A17: Operational Kantor | B17: =IF(C4=0,0,C17/C4) -> 0.01 | C17: =SUMIF($D$3:$BK$3,"Rp",$D17:$BK17) -> 7161657 | D17: 0.01 | E17: =D17*E$4 -> 447415 | F17: 0.01 | G17: =F17*G$4 -> 945502.5 | H17: 0.01 | I17: =H17*I$4 -> 250798 | J17: 0.01 | K17: =J17*K$4 -> 112476.5 | L17: 0.01 | M17: =L17*M$4 -> 171812.5 | N17: 0.01 | O17: =N17*O$4 -> 178949 | P17: 0.01 | Q17: =P17*Q$4 -> 115636 | R17: 0.01 | S17: =R17*S$4 -> 200210 | T17: 0.01 | U17: =T17*U$4 -> 336551 | V17: 0.01 | W17: =V17*W$4 -> 107273 | X17: 0.01 | Y17: =X17*Y$4 -> 433622 | Z17: 0.01 | AA17: =Z17*AA$4 -> 188782 | AB17: 0.01 | AC17: =AB17*AC$4 -> 163186 | AD17: 0.01 | AE17: =AD17*AE$4 -> 189456 | AF17: 0.01 | AG17: =AF17*AG$4 -> 191284.5 | AH17: 0.01 | AI17: =AH17*AI$4 -> 165816 | AJ17: 0.01 | AK17: =AJ17*AK$4 -> 341258 | AL17: 0.01 | AM17: =AL17*AM$4 -> 322758.5 | AN17: 0.01 | AO17: =AN17*AO$4 -> 94408.5 | AP17: 0.01 | AQ17: =AP17*AQ$4 -> 139493 | AR17: 0.01 | AS17: =AR17*AS$4 -> 134471 | AT17: 0.01 | AU17: =AT17*AU$4 -> 421020.5 | AV17: 0.01 | AW17: =AV17*AW$4 -> 181794 | AX17: 0.01 | AY17: =AX17*AY$4 -> 544445.5 | AZ17: 0.01 | BA17: =AZ17*BA$4 -> 142709 | BB17: 0.01 | BC17: =BB17*BC$4 -> 220495 | BD17: 0.01 | BE17: =BD17*BE$4 -> 7770.5 | BF17: 0.01 | BG17: =BF17*BG$4 -> 195432.5 | BH17: 0.01 | BI17: =BH17*BI$4 -> 139289 | BJ17: 0.01 | BK17: =BJ17*BK$4 -> 77542
A18: Motor dan Mobil | B18: =IF(C4=0,0,C18/C4) -> 0 | C18: =SUMIF($D$3:$BK$3,"Rp",$D18:$BK18) -> 0 | D18: 0 | E18: =D18*E$4 -> 0 | F18: 0 | G18: =F18*G$4 -> 0 | H18: 0 | I18: =H18*I$4 -> 0 | J18: 0 | K18: =J18*K$4 -> 0 | L18: 0 | M18: =L18*M$4 -> 0 | N18: 0 | O18: =N18*O$4 -> 0 | P18: 0 | Q18: =P18*Q$4 -> 0 | R18: 0 | S18: =R18*S$4 -> 0 | T18: 0 | U18: =T18*U$4 -> 0 | V18: 0 | W18: =V18*W$4 -> 0 | X18: 0 | Y18: =X18*Y$4 -> 0 | Z18: 0 | AA18: =Z18*AA$4 -> 0 | AB18: 0 | AC18: =AB18*AC$4 -> 0 | AD18: 0 | AE18: =AD18*AE$4 -> 0 | AF18: 0 | AG18: =AF18*AG$4 -> 0 | AH18: 0 | AI18: =AH18*AI$4 -> 0 | AJ18: 0 | AK18: =AJ18*AK$4 -> 0 | AL18: 0 | AM18: =AL18*AM$4 -> 0 | AN18: 0 | AO18: =AN18*AO$4 -> 0 | AP18: 0 | AQ18: =AP18*AQ$4 -> 0 | AR18: 0 | AS18: =AR18*AS$4 -> 0 | AT18: 0 | AU18: =AT18*AU$4 -> 0 | AV18: 0 | AW18: =AV18*AW$4 -> 0 | AX18: 0 | AY18: =AX18*AY$4 -> 0 | AZ18: 0 | BA18: =AZ18*BA$4 -> 0 | BB18: 0 | BC18: =BB18*BC$4 -> 0 | BD18: 0 | BE18: =BD18*BE$4 -> 0 | BF18: 0 | BG18: =BF18*BG$4 -> 0 | BH18: 0 | BI18: =BH18*BI$4 -> 0 | BJ18: 0 | BK18: =BJ18*BK$4 -> 0
A19: Homebase | B19: =IF(C4=0,0,C19/C4) -> 0 | C19: =SUMIF($D$3:$BK$3,"Rp",$D19:$BK19) -> 0 | D19: 0 | E19: =D19*E$4 -> 0 | F19: 0 | G19: =F19*G$4 -> 0 | H19: 0 | I19: =H19*I$4 -> 0 | J19: 0 | K19: =J19*K$4 -> 0 | L19: 0 | M19: =L19*M$4 -> 0 | N19: 0 | O19: =N19*O$4 -> 0 | P19: 0 | Q19: =P19*Q$4 -> 0 | R19: 0 | S19: =R19*S$4 -> 0 | T19: 0 | U19: =T19*U$4 -> 0 | V19: 0 | W19: =V19*W$4 -> 0 | X19: 0 | Y19: =X19*Y$4 -> 0 | Z19: 0 | AA19: =Z19*AA$4 -> 0 | AB19: 0 | AC19: =AB19*AC$4 -> 0 | AD19: 0 | AE19: =AD19*AE$4 -> 0 | AF19: 0 | AG19: =AF19*AG$4 -> 0 | AH19: 0 | AI19: =AH19*AI$4 -> 0 | AJ19: 0 | AK19: =AJ19*AK$4 -> 0 | AL19: 0 | AM19: =AL19*AM$4 -> 0 | AN19: 0 | AO19: =AN19*AO$4 -> 0 | AP19: 0 | AQ19: =AP19*AQ$4 -> 0 | AR19: 0 | AS19: =AR19*AS$4 -> 0 | AT19: 0 | AU19: =AT19*AU$4 -> 0 | AV19: 0 | AW19: =AV19*AW$4 -> 0 | AX19: 0 | AY19: =AX19*AY$4 -> 0 | AZ19: 0 | BA19: =AZ19*BA$4 -> 0 | BB19: 0 | BC19: =BB19*BC$4 -> 0 | BD19: 0 | BE19: =BD19*BE$4 -> 0 | BF19: 0 | BG19: =BF19*BG$4 -> 0 | BH19: 0 | BI19: =BH19*BI$4 -> 0 | BJ19: 0 | BK19: =BJ19*BK$4 -> 0
A20: Allowance Kunjungan include ops permit | B20: =IF(C4=0,0,C20/C4) -> 0.014177669 | C20: =SUMIF($D$3:$BK$3,"Rp",$D20:$BK20) -> 10153560 | D20: 0.01 | E20: =D20*E$4 -> 447415 | F20: 0.01 | G20: =F20*G$4 -> 945502.5 | H20: 0.01 | I20: =H20*I$4 -> 250798 | J20: 0.01 | K20: =J20*K$4 -> 112476.5 | L20: 0.005 | M20: =L20*M$4 -> 85906.25 | N20: 0.025 | O20: =N20*O$4 -> 447372.5 | P20: 0.01 | Q20: =P20*Q$4 -> 115636 | R20: 0.025 | S20: =R20*S$4 -> 500525 | T20: 0.025 | U20: =T20*U$4 -> 841377.5 | V20: 0.01 | W20: =V20*W$4 -> 107273 | X20: 0.01 | Y20: =X20*Y$4 -> 433622 | Z20: 0.025 | AA20: =Z20*AA$4 -> 471955 | AB20: 0.025 | AC20: =AB20*AC$4 -> 407965 | AD20: 0.01 | AE20: =AD20*AE$4 -> 189456 | AF20: 0.025 | AG20: =AF20*AG$4 -> 478211.25 | AH20: 0.025 | AI20: =AH20*AI$4 -> 414540 | AJ20: 0.01 | AK20: =AJ20*AK$4 -> 341258 | AL20: 0.01 | AM20: =AL20*AM$4 -> 322758.5 | AN20: 0.01 | AO20: =AN20*AO$4 -> 94408.5 | AP20: 0.025 | AQ20: =AP20*AQ$4 -> 348732.5 | AR20: 0.01 | AS20: =AR20*AS$4 -> 134471 | AT20: 0.01 | AU20: =AT20*AU$4 -> 421020.5 | AV20: 0.025 | AW20: =AV20*AW$4 -> 454485 | AX20: 0.01 | AY20: =AX20*AY$4 -> 544445.5 | AZ20: 0.01 | BA20: =AZ20*BA$4 -> 142709 | BB20: 0.025 | BC20: =BB20*BC$4 -> 551237.5 | BD20: 0.025 | BE20: =BD20*BE$4 -> 19426.25 | BF20: 0.01 | BG20: =BF20*BG$4 -> 195432.5 | BH20: 0.01 | BI20: =BH20*BI$4 -> 139289 | BJ20: 0.025 | BK20: =BJ20*BK$4 -> 193855
A21: Marketing cost | B21: =IF(C4=0,0,C21/C4) -> 0.0099520188 | C21: =SUMIF($D$3:$BK$3,"Rp",$D21:$BK21) -> 7127294.5 | D21: 0.01 | E21: =D21*E$4 -> 447415 | F21: 0.01 | G21: =F21*G$4 -> 945502.5 | H21: 0.01 | I21: =H21*I$4 -> 250798 | J21: 0.01 | K21: =J21*K$4 -> 112476.5 | L21: 0.008 | M21: =L21*M$4 -> 137450 | N21: 0.01 | O21: =N21*O$4 -> 178949 | P21: 0.01 | Q21: =P21*Q$4 -> 115636 | R21: 0.01 | S21: =R21*S$4 -> 200210 | T21: 0.01 | U21: =T21*U$4 -> 336551 | V21: 0.01 | W21: =V21*W$4 -> 107273 | X21: 0.01 | Y21: =X21*Y$4 -> 433622 | Z21: 0.01 | AA21: =Z21*AA$4 -> 188782 | AB21: 0.01 | AC21: =AB21*AC$4 -> 163186 | AD21: 0.01 | AE21: =AD21*AE$4 -> 189456 | AF21: 0.01 | AG21: =AF21*AG$4 -> 191284.5 | AH21: 0.01 | AI21: =AH21*AI$4 -> 165816 | AJ21: 0.01 | AK21: =AJ21*AK$4 -> 341258 | AL21: 0.01 | AM21: =AL21*AM$4 -> 322758.5 | AN21: 0.01 | AO21: =AN21*AO$4 -> 94408.5 | AP21: 0.01 | AQ21: =AP21*AQ$4 -> 139493 | AR21: 0.01 | AS21: =AR21*AS$4 -> 134471 | AT21: 0.01 | AU21: =AT21*AU$4 -> 421020.5 | AV21: 0.01 | AW21: =AV21*AW$4 -> 181794 | AX21: 0.01 | AY21: =AX21*AY$4 -> 544445.5 | AZ21: 0.01 | BA21: =AZ21*BA$4 -> 142709 | BB21: 0.01 | BC21: =BB21*BC$4 -> 220495 | BD21: 0.01 | BE21: =BD21*BE$4 -> 7770.5 | BF21: 0.01 | BG21: =BF21*BG$4 -> 195432.5 | BH21: 0.01 | BI21: =BH21*BI$4 -> 139289 | BJ21: 0.01 | BK21: =BJ21*BK$4 -> 77542
A22: Outflow | B22: =IF(C6=0,0,C22/C6) -> 1.0109123 | C22: =SUMIF($D$3:$BK$3,"Rp",$D22:$BK22) -> 7.2398074e+08 | D22: =IF(E6=0,0,E22/E6) -> 1.034 | E22: =SUM(E8:E21)-IF(Rekap!$C$5="Ya",0,E13) -> 46262711 | F22: =IF(G6=0,0,G22/G6) -> 1.0290242 | G22: =SUM(G8:G21)-IF(Rekap!$C$5="Ya",0,G13) -> 97294500 | H22: =IF(I6=0,0,I22/I6) -> 1.0223399 | I22: =SUM(I8:I21)-IF(Rekap!$C$5="Ya",0,I13) -> 25640080 | J22: =IF(K6=0,0,K22/K6) -> 1.0273973 | K22: =SUM(K8:K21)-IF(Rekap!$C$5="Ya",0,K13) -> 11555805 | L22: =IF(M6=0,0,M22/M6) -> 1.0381539 | M22: =SUM(M8:M21)-IF(Rekap!$C$5="Ya",0,M13) -> 17836782 | N22: =IF(O6=0,0,O22/O6) -> 0.97047823 | O22: =SUM(O8:O21)-IF(Rekap!$C$5="Ya",0,O13) -> 17366611 | P22: =IF(Q6=0,0,Q22/Q6) -> 1.0081603 | Q22: =SUM(Q8:Q21)-IF(Rekap!$C$5="Ya",0,Q13) -> 11657963 | R22: =IF(S6=0,0,S22/S6) -> 0.91976834 | S22: =SUM(S8:S21)-IF(Rekap!$C$5="Ya",0,S13) -> 18414682 | T22: =IF(U6=0,0,U22/U6) -> 0.97074661 | U22: =SUM(U8:U21)-IF(Rekap!$C$5="Ya",0,U13) -> 32670574 | V22: =IF(W6=0,0,W22/W6) -> 0.99309103 | W22: =SUM(W8:W21)-IF(Rekap!$C$5="Ya",0,W13) -> 10653185 | X22: =IF(Y6=0,0,Y22/Y6) -> 1.1105199 | Y22: =SUM(Y8:Y21)-IF(Rekap!$C$5="Ya",0,Y13) -> 48154586 | Z22: =IF(AA6=0,0,AA22/AA6) -> 0.9970169 | AA22: =SUM(AA8:AA21)-IF(Rekap!$C$5="Ya",0,AA13) -> 18821884 | AB22: =IF(AC6=0,0,AC22/AC6) -> 1.0057129 | AC22: =SUM(AC8:AC21)-IF(Rekap!$C$5="Ya",0,AC13) -> 16411826 | AD22: =IF(AE6=0,0,AE22/AE6) -> 1.0103311 | AE22: =SUM(AE8:AE21)-IF(Rekap!$C$5="Ya",0,AE13) -> 19141329 | AF22: =IF(AG6=0,0,AG22/AG6) -> 1.0465286 | AG22: =SUM(AG8:AG21)-IF(Rekap!$C$5="Ya",0,AG13) -> 20018470 | AH22: =IF(AI6=0,0,AI22/AI6) -> 1.069501 | AI22: =SUM(AI8:AI21)-IF(Rekap!$C$5="Ya",0,AI13) -> 17734037 | AJ22: =IF(AK6=0,0,AK22/AK6) -> 0.96812217 | AK22: =SUM(AK8:AK21)-IF(Rekap!$C$5="Ya",0,AK13) -> 33037943 | AL22: =IF(AM6=0,0,AM22/AM6) -> 0.99353381 | AM22: =SUM(AM8:AM21)-IF(Rekap!$C$5="Ya",0,AM13) -> 32067148 | AN22: =IF(AO6=0,0,AO22/AO6) -> 1.0081167 | AO22: =SUM(AO8:AO21)-IF(Rekap!$C$5="Ya",0,AO13) -> 9517478.3 | AP22: =IF(AQ6=0,0,AQ22/AQ6) -> 1.0117863 | AQ22: =SUM(AQ8:AQ21)-IF(Rekap!$C$5="Ya",0,AQ13) -> 14113711 | AR22: =IF(AS6=0,0,AS22/AS6) -> 0.97125408 | AS22: =SUM(AS8:AS21)-IF(Rekap!$C$5="Ya",0,AS13) -> 13060551 | AT22: =IF(AU6=0,0,AU22/AU6) -> 0.99283671 | AU22: =SUM(AU8:AU21)-IF(Rekap!$C$5="Ya",0,AU13) -> 41800461 | AV22: =IF(AW6=0,0,AW22/AW6) -> 1.001 | AW22: =SUM(AW8:AW21)-IF(Rekap!$C$5="Ya",0,AW13) -> 18197579 | AX22: =IF(AY6=0,0,AY22/AY6) -> 1.0220249 | AY22: =SUM(AY8:AY21)-IF(Rekap!$C$5="Ya",0,AY13) -> 55643686 | AZ22: =IF(BA6=0,0,BA22/BA6) -> 1.020335 | BA22: =SUM(BA8:BA21)-IF(Rekap!$C$5="Ya",0,BA13) -> 14561098 | BB22: =IF(BC6=0,0,BC22/BC6) -> 0.99778947 | BC22: =SUM(BC8:BC21)-IF(Rekap!$C$5="Ya",0,BC13) -> 22000759 | BD22: =IF(BE6=0,0,BE22/BE6) -> 0.7084436 | BE22: =SUM(BE8:BE21)-IF(Rekap!$C$5="Ya",0,BE13) -> 550496.1 | BF22: =IF(BG6=0,0,BG22/BG6) -> 0.97763184 | BG22: =SUM(BG8:BG21)-IF(Rekap!$C$5="Ya",0,BG13) -> 19106104 | BH22: =IF(BI6=0,0,BI22/BI6) -> 0.92805204 | BI22: =SUM(BI8:BI21)-IF(Rekap!$C$5="Ya",0,BI13) -> 12926744 | BJ22: =IF(BK6=0,0,BK22/BK6) -> 1.001 | BK22: =SUM(BK8:BK21)-IF(Rekap!$C$5="Ya",0,BK13) -> 7761954.2
A23: Profit | B23: =IF(C6=0,0,C23/C6) -> -0.010912331 | C23: =SUMIF($D$3:$BK$3,"Rp",$D23:$BK23) -> -7815037.4 | D23: =IF(E6=0,0,E23/E6) -> -0.034 | E23: =E6-E22 -> -1521211 | F23: =IF(G6=0,0,G23/G6) -> -0.029024244 | G23: =G6-G22 -> -2744249.5 | H23: =IF(I6=0,0,I23/I6) -> -0.022339907 | I23: =I6-I22 -> -560280.4 | J23: =IF(K6=0,0,K23/K6) -> -0.027397252 | K23: =K6-K22 -> -308154.7 | L23: =IF(M6=0,0,M23/M6) -> -0.038153911 | M23: =M6-M22 -> -655531.88 | N23: =IF(O6=0,0,O23/O6) -> 0.029521774 | O23: =O6-O22 -> 528289.2 | P23: =IF(Q6=0,0,Q23/Q6) -> -0.0081603307 | Q23: =Q6-Q22 -> -94362.8 | R23: =IF(S6=0,0,S23/S6) -> 0.080231657 | S23: =S6-S22 -> 1606318 | T23: =IF(U6=0,0,U23/U6) -> 0.029253391 | U23: =U6-U22 -> 984525.8 | V23: =IF(W6=0,0,W23/W6) -> 0.0069089706 | W23: =W6-W22 -> 74114.6 | X23: =IF(Y6=0,0,Y23/Y6) -> -0.11051989 | Y23: =Y6-Y22 -> -4792385.6 | Z23: =IF(AA6=0,0,AA23/AA6) -> 0.0029831022 | AA23: =AA6-AA22 -> 56315.6 | AB23: =IF(AC6=0,0,AC23/AC6) -> -0.0057128798 | AC23: =AC6-AC22 -> -93226.2 | AD23: =IF(AE6=0,0,AE23/AE6) -> -0.010331095 | AE23: =AE6-AE22 -> -195728.8 | AF23: =IF(AG6=0,0,AG23/AG6) -> -0.046528595 | AG23: =AG6-AG22 -> -890019.9 | AH23: =IF(AI6=0,0,AI23/AI6) -> -0.069500965 | AI23: =AI6-AI22 -> -1152437.2 | AJ23: =IF(AK6=0,0,AK23/AK6) -> 0.031877834 | AK23: =AK6-AK22 -> 1087856.6 | AL23: =IF(AM6=0,0,AM23/AM6) -> 0.0064661876 | AM23: =AM6-AM22 -> 208701.7 | AN23: =IF(AO6=0,0,AO23/AO6) -> -0.0081166738 | AO23: =AO6-AO22 -> -76628.3 | AP23: =IF(AQ6=0,0,AQ23/AQ6) -> -0.011786298 | AQ23: =AQ6-AQ22 -> -164410.6 | AR23: =IF(AS6=0,0,AS23/AS6) -> 0.028745915 | AS23: =AS6-AS22 -> 386549.2 | AT23: =IF(AU6=0,0,AU23/AU6) -> 0.0071632878 | AU23: =AU6-AU22 -> 301589.1 | AV23: =IF(AW6=0,0,AW23/AW6) -> -0.001 | AW23: =AW6-AW22 -> -18179.4 | AX23: =IF(AY6=0,0,AY23/AY6) -> -0.022024902 | AY23: =AY6-AY22 -> -1199135.9 | AZ23: =IF(BA6=0,0,BA23/BA6) -> -0.020334961 | BA23: =BA6-BA22 -> -290198.2 | BB23: =IF(BC6=0,0,BC23/BC6) -> 0.0022105263 | BC23: =BC6-BC22 -> 48741 | BD23: =IF(BE6=0,0,BE23/BE6) -> 0.2915564 | BE23: =BE6-BE22 -> 226553.9 | BF23: =IF(BG6=0,0,BG23/BG6) -> 0.022368158 | BG23: =BG6-BG22 -> 437146.5 | BH23: =IF(BI6=0,0,BI23/BI6) -> 0.071947961 | BI23: =BI6-BI22 -> 1002155.9 | BJ23: =IF(BK6=0,0,BK23/BK6) -> -0.001 | BK23: =BK6-BK22 -> -7754.2
A25: Catatan:
A26: • Sel biru/kuning = input. Nilai PO & % biaya diambil dari sheet project di file RAB Project TELCO.
A27: • Interest Bank = (% di Rekap!C4) × Dana Investor. Retensi masuk biaya/Dana Investor atau tidak diatur di Rekap!C5.
A28: • Pajak dihitung dari Nilai Proyek; Retensi & Cost Project dihitung dari Nilai PO Implementasi.
A29: • Kolom TOTAL menjumlah semua cluster otomatis.

Sheet Form ADW
A1: FORM PENGAJUAN DANA
A2: PT Indotek Buana Karya — Modal Kerja Proyek ADW 2026
A3: Sel kuning = diisi pemohon. Pilih cluster di "Nama Proyek"; angka budget otomatis ditarik dari sheet ADW.
A5: No. Pengajuan | C5: FPD/ADW/2026/10/001 | F5: Diajukan Oleh | H5: Pemohon Demo
A6: Tanggal Pengajuan | C6: 46308 | F6: Jabatan / Divisi | K6: helper (kolom ini boleh disembunyikan)
A7: Nama Proyek | C7: WANASARI RW 01 SUBANG | F7: Diajukan Kepada | H7: Investor | K7: =MATCH($C$7,ADW!$1:$1,0) -> 40
A8: Pemberi Kerja | C8: PT ADW | F8: Termin Pencairan Ke- | H8: 1
A9: Nilai Proyek (Rp) | C9: =INDEX(ADW!$6:$6,$K$7+1) -> 9440850 | F9: Periode Penggunaan | H9: Oktober
A11: RINCIAN KEBUTUHAN DANA
A12: No | B12: Pos Anggaran | C12: % Nilai Proyek | D12: Budget (Rp) | E12: % Dicairkan | F12: Diajukan Saat Ini (Rp) | G12: Sudah Dicairkan Sblm (Rp) | H12: Sisa Budget (Rp) | I12: Keterangan / Peruntukan
A13: A | B13: SUBCON, PERMIT & PAJAK
A14: 1 | B14: =TRIM(ADW!$A$8) -> Biaya Subcon | C14: =IF($C$9=0,0,D14/$C$9) -> 0.7364697 | D14: =INDEX(ADW!$8:$8,$K$7+1) -> 6952900 | E14: 1 | F14: =ROUND(D14*E14,0) -> 6952900 | G14: 0 | H14: =ROUND(D14,0)-G14-F14 -> 0 | I14: Pembayaran subcon
A15: 2 | B15: =TRIM(ADW!$A$9) -> Biaya Permit | C15: =IF($C$9=0,0,D15/$C$9) -> 0 | D15: =INDEX(ADW!$9:$9,$K$7+1) -> 0 | E15: 1 | F15: =ROUND(D15*E15,0) -> 0 | G15: 0 | H15: =ROUND(D15,0)-G15-F15 -> 0 | I15: Permit (pass-through)
A16: 3 | B16: =TRIM(ADW!$A$10) -> Ticket Internal | C16: =IF($C$9=0,0,D16/$C$9) -> 0 | D16: =INDEX(ADW!$10:$10,$K$7+1) -> 0 | E16: 1 | F16: =ROUND(D16*E16,0) -> 0 | G16: 0 | H16: =ROUND(D16,0)-G16-F16 -> 0 | I16: Tiket perjalanan
A17: 4 | B17: =TRIM(ADW!$A$12) -> Pajak | C17: =IF($C$9=0,0,D17/$C$9) -> 0.025 | D17: =INDEX(ADW!$12:$12,$K$7+1) -> 236021.25 | E17: 1 | F17: =ROUND(D17*E17,0) -> 236021 | G17: 0 | H17: =ROUND(D17,0)-G17-F17 -> 0 | I17: Pajak atas nilai proyek
B18: Subtotal A | C18: =SUM(C14:C17) -> 0.7614697 | D18: =SUM(D14:D17) -> 7188921.2 | F18: =SUM(F14:F17) -> 7188921 | G18: =SUM(G14:G17) -> 0 | H18: =SUM(H14:H17) -> 0
A19: B | B19: COST PROJECT
A20: 1 | B20: =TRIM(ADW!$A$15) -> Indirect Cost | C20: =IF($C$9=0,0,D20/$C$9) -> 0.01 | D20: =INDEX(ADW!$15:$15,$K$7+1) -> 94408.5 | E20: 1 | F20: =ROUND(D20*E20,0) -> 94409 | G20: 0 | H20: =ROUND(D20,0)-G20-F20 -> 0
A21: 2 | B21: =TRIM(ADW!$A$16) -> Direct Cost | C21: =IF($C$9=0,0,D21/$C$9) -> 0.015 | D21: =INDEX(ADW!$16:$16,$K$7+1) -> 141612.75 | E21: 1 | F21: =ROUND(D21*E21,0) -> 141613 | G21: 0 | H21: =ROUND(D21,0)-G21-F21 -> 0 | I21: Gaji/upah teknisi lapangan
A22: 3 | B22: =TRIM(ADW!$A$17) -> Operational Kantor | C22: =IF($C$9=0,0,D22/$C$9) -> 0.01 | D22: =INDEX(ADW!$17:$17,$K$7+1) -> 94408.5 | E22: 1 | F22: =ROUND(D22*E22,0) -> 94409 | G22: 0 | H22: =ROUND(D22,0)-G22-F22 -> 0
A23: 4 | B23: =TRIM(ADW!$A$18) -> Motor dan Mobil | C23: =IF($C$9=0,0,D23/$C$9) -> 0 | D23: =INDEX(ADW!$18:$18,$K$7+1) -> 0 | E23: 1 | F23: =ROUND(D23*E23,0) -> 0 | G23: 0 | H23: =ROUND(D23,0)-G23-F23 -> 0 | I23: Sewa/BBM kendaraan
A24: 5 | B24: =TRIM(ADW!$A$19) -> Homebase | C24: =IF($C$9=0,0,D24/$C$9) -> 0 | D24: =INDEX(ADW!$19:$19,$K$7+1) -> 0 | E24: 1 | F24: =ROUND(D24*E24,0) -> 0 | G24: 0 | H24: =ROUND(D24,0)-G24-F24 -> 0
A25: 6 | B25: =TRIM(ADW!$A$20) -> Allowance Kunjungan include ops permit | C25: =IF($C$9=0,0,D25/$C$9) -> 0.01 | D25: =INDEX(ADW!$20:$20,$K$7+1) -> 94408.5 | E25: 1 | F25: =ROUND(D25*E25,0) -> 94409 | G25: 0 | H25: =ROUND(D25,0)-G25-F25 -> 0 | I25: Termasuk ops permit
A26: 7 | B26: =TRIM(ADW!$A$21) -> Marketing cost | C26: =IF($C$9=0,0,D26/$C$9) -> 0.01 | D26: =INDEX(ADW!$21:$21,$K$7+1) -> 94408.5 | E26: 1 | F26: =ROUND(D26*E26,0) -> 94409 | G26: 0 | H26: =ROUND(D26,0)-G26-F26 -> 0
B27: Subtotal B | C27: =SUM(C20:C26) -> 0.055 | D27: =SUM(D20:D26) -> 519246.75 | F27: =SUM(F20:F26) -> 519249 | G27: =SUM(G20:G26) -> 0 | H27: =SUM(H20:H26) -> 0
B28: TOTAL PENGAJUAN | C28: =C18+C27 -> 0.8164697 | D28: =D18+D27 -> 7708168 | F28: =F18+F27 -> 7708170 | G28: =G18+G27 -> 0 | H28: =H18+H27 -> 0
A30: INFORMASI PENDUKUNG (tidak termasuk pengajuan) | K30: =ROUND(F28,0) -> 7708170
A31: ="Beban bunga dana investor ("&TEXT(Rekap!$C$4,"0%")&" × dana investor)" -> Beban bunga dana investor (10% × dana investor) | D31: =INDEX(ADW!$11:$11,$K$7+1) -> 865225.3 | K31: =INT(K30/1000000000) -> 0
A32: Cadangan budget / retensi | D32: =INDEX(ADW!$13:$13,$K$7+1) -> 944085 | K32: =INT(MOD(K30,1000000000)/1000000) -> 7
A33: Proyeksi profit cluster | D33: =INDEX(ADW!$23:$23,$K$7+1) -> -76628.3 | K33: =INT(MOD(K30,1000000)/1000) -> 708
A34: Margin profit | D34: =INDEX(ADW!$23:$23,$K$7) -> -0.0081166738 | K34: =MOD(K30,1000) -> 170
K35: =TRIM(IF(K31>0,VLOOKUP(K31,_terbilang!$A$1:$B$999,2,FALSE())&" milyar ","")&IF(K32>0,VLOOKUP(K32,_terbilang!$A$1:$B$999,2,FALSE())&" juta ","")&IF(K33=1,"seribu ",IF(K33>0,VLOOKUP(K33,_terbilang!$A$1:$B$999,2,FALSE())&" ribu ",""))&IF(K34>0,VLOOKUP(K34,_terbilang!$A$1:$B$999,2,FALSE()),""))&" rupiah" -> tujuh juta tujuh ratus delapan ribu seratus tujuh puluh rupiah
A36: Terbilang | C36: =IF(K30=0,"Nol rupiah",UPPER(LEFT(K35,1))&MID(K35,2,500)) -> Tujuh juta tujuh ratus delapan ribu seratus tujuh puluh rupiah
A37: Tujuan / Justifikasi Penggunaan Dana | C37: ="Modal kerja pelaksanaan pekerjaan FTTH "&C7&" untuk "&C8&"." -> Modal kerja pelaksanaan pekerjaan FTTH WANASARI RW 01 SUBANG untuk PT ADW.
A41: REKENING TUJUAN PENCAIRAN
A42: Nama Bank | C42: BCA
A43: No. Rekening | C43: 1234567890
A44: Atas Nama | C44: Pemohon Demo
A46: LAMPIRAN (beri tanda ✓)
A47: ✓ | B47: Proyeksi budget proyek (sheet ADW) | E47: ✓ | F47: ="PO / SPK dengan "&C8 -> PO / SPK dengan PT ADW
...

Sheet EVANTAMA
A1: Proyeksi Project EVANTAMA 2026 | B1: TOTAL EVANTAMA | D1: Cluster Sinagar Tasik | F1: Cluster Kersanagara RW 08 Tasik | H1: Cluster Kersanagara RW 04 Tasik
D2: Permit PO 665/PERMIT/ENS/0726 · PO Cluster: 754/FTTH/ENS/0826 PO Subfeeder: 978/FTTH/ENS/0926 | F2: Permit PO 668/PERMIT/ENS/0726 · PO Cluster: 976/FTTH/ENS/0926 PO Subfeeder: 977/FTTH/ENS/0926 | H2: Permit PO 969/FTTH/ENS/0926 · PO Cluster: 979/FTTH/ENS/0926 PO Subfeeder: 980/FTTH/ENS/0926
B3: % | C3: Rp | D3: % | E3: Rp | F3: % | G3: Rp | H3: % | I3: Rp
A4: Nilai PO Implementasi | C4: =SUMIF($D$3:$I$3,"Rp",$D4:$I4) -> 185454823 | E4: 108940677 | G4: 34882758 | I4: 41631388
A5: Nilai PO Permit | C5: =SUMIF($D$3:$I$3,"Rp",$D5:$I5) -> 51000000 | E5: 37000000 | G5: 9000000 | I5: 5000000
A6: Nilai Proyek | C6: =SUMIF($D$3:$I$3,"Rp",$D6:$I6) -> 236454823 | E6: =E4+E5 -> 145940677 | G6: =G4+G5 -> 43882758 | I6: =I4+I5 -> 46631388
A7: DUIT INVESTOR | B7: =IF(C6=0,0,C7/C6) -> 0.95814547 | C7: =SUMIF($D$3:$I$3,"Rp",$D7:$I7) -> 2.2655812e+08 | D7: =IF(E6=0,0,E7/E6) -> 0.95492282 | E7: =E8+E9+E10+E12+IF(Rekap!$C$5="Ya",E13,0)+SUM(E15:E21) -> 1.3936208e+08 | F7: =IF(G6=0,0,G7/G6) -> 0.98823289 | G7: =G8+G9+G10+G12+IF(Rekap!$C$5="Ya",G13,0)+SUM(G15:G21) -> 43366385 | H7: =IF(I6=0,0,I7/I6) -> 0.93991732 | I7: =I8+I9+I10+I12+IF(Rekap!$C$5="Ya",I13,0)+SUM(I15:I21) -> 43829649
A8: Biaya Subcon | B8: =IF(C4=0,0,C8/C4) -> 0.63192458 | C8: =SUMIF($D$3:$I$3,"Rp",$D8:$I8) -> 1.1719346e+08 | D8: =IF(E$4=0,0,E8/E$4) -> 0.66290568 | E8: 72217394 | F8: =IF(G$4=0,0,G8/G$4) -> 0.57326987 | G8: 19997234 | H8: =IF(I$4=0,0,I8/I$4) -> 0.6 | I8: 24978833
A9: Biaya Permit | B9: =IF(C4=0,0,C9/C4) -> 0.27499959 | C9: =SUMIF($D$3:$I$3,"Rp",$D9:$I9) -> 51000000 | D9: =IF(E$5=0,0,E9/E$5) -> 1 | E9: 37000000 | F9: =IF(G$5=0,0,G9/G$5) -> 1 | G9: 9000000 | H9: =IF(I$5=0,0,I9/I$5) -> 1 | I9: 5000000
A10: Ticket Internal | B10: =IF(C4=0,0,C10/C4) -> 0 | C10: =SUMIF($D$3:$I$3,"Rp",$D10:$I10) -> 0 | D10: 0 | E10: =D10*E$4 -> 0 | F10: 0 | G10: =F10*G$4 -> 0 | H10: 0 | I10: =H10*I$4 -> 0
A11: Interest Bank | B11: =IF(C7=0,0,C11/C7) -> 0.1 | C11: =SUMIF($D$3:$I$3,"Rp",$D11:$I11) -> 22655812 | D11: =Rekap!$C$4 -> 0.1 | E11: =D11*E$7 -> 13936208 | F11: =Rekap!$C$4 -> 0.1 | G11: =F11*G$7 -> 4336638.5 | H11: =Rekap!$C$4 -> 0.1 | I11: =H11*I$7 -> 4382964.9
A12: Pajak | B12: =IF(C6=0,0,C12/C6) -> 0.0265 | C12: =SUMIF($D$3:$I$3,"Rp",$D12:$I12) -> 6266052.8 | D12: 0.0265 | E12: =D12*E$6 -> 3867427.9 | F12: 0.0265 | G12: =F12*G$6 -> 1162893.1 | H12: 0.0265 | I12: =H12*I$6 -> 1235731.8
A13: Retensi | B13: =IF(C4=0,0,C13/C4) -> 0.1 | C13: =SUMIF($D$3:$I$3,"Rp",$D13:$I13) -> 18545482 | D13: 0.1 | E13: =D13*E$4 -> 10894068 | F13: 0.1 | G13: =F13*G$4 -> 3488275.8 | H13: 0.1 | I13: =H13*I$4 -> 4163138.8
A14: COST PROJECT
A15: Indirect Cost | B15: =IF(C4=0,0,C15/C4) -> 0.01663276 | C15: =SUMIF($D$3:$I$3,"Rp",$D15:$I15) -> 3084625.6 | D15: 0.02 | E15: =D15*E$4 -> 2178813.5 | F15: 0.02 | G15: =F15*G$4 -> 697655.16 | H15: 0.005 | I15: =H15*I$4 -> 208156.94
A16: Direct Cost | B16: =IF(C4=0,0,C16/C4) -> 0.033265521 | C16: =SUMIF($D$3:$I$3,"Rp",$D16:$I16) -> 6169251.3 | D16: 0.04 | E16: =D16*E$4 -> 4357627.1 | F16: 0.04 | G16: =F16*G$4 -> 1395310.3 | H16: 0.01 | I16: =H16*I$4 -> 416313.88
A17: Operational Kantor | B17: =IF(C4=0,0,C17/C4) -> 0.057887953 | C17: =SUMIF($D$3:$I$3,"Rp",$D17:$I17) -> 10735600 | D17: =IF(E$4=0,0,E17/E$4) -> 0.032848459 | E17: 3578533.3 | F17: =IF(G$4=0,0,G17/G$4) -> 0.10258745 | G17: 3578533.3 | H17: =IF(I$4=0,0,I17/I$4) -> 0.085957579 | I17: 3578533.3
A18: Motor dan Mobil | B18: =IF(C4=0,0,C18/C4) -> 0 | C18: =SUMIF($D$3:$I$3,"Rp",$D18:$I18) -> 0 | D18: 0 | E18: =D18*E$4 -> 0 | F18: 0 | G18: =F18*G$4 -> 0 | H18: 0 | I18: =H18*I$4 -> 0
A19: Homebase | B19: =IF(C4=0,0,C19/C4) -> 0.04313719 | C19: =SUMIF($D$3:$I$3,"Rp",$D19:$I19) -> 8000000 | D19: =IF(E$4=0,0,E19/E$4) -> 0.018358615 | E19: 2000000 | F19: =IF(G$4=0,0,G19/G$4) -> 0.086002374 | G19: 3000000 | H19: =IF(I$4=0,0,I19/I$4) -> 0.072061013 | I19: 3000000
A20: Allowance Kunjungan include ops permit | B20: =IF(C4=0,0,C20/C4) -> 0.02 | C20: =SUMIF($D$3:$I$3,"Rp",$D20:$I20) -> 3709096.5 | D20: 0.02 | E20: =D20*E$4 -> 2178813.5 | F20: 0.02 | G20: =F20*G$4 -> 697655.16 | H20: 0.02 | I20: =H20*I$4 -> 832627.76
A21: Marketing cost | B21: =IF(C4=0,0,C21/C4) -> 0.01 | C21: =SUMIF($D$3:$I$3,"Rp",$D21:$I21) -> 1854548.2 | D21: 0.01 | E21: =D21*E$4 -> 1089406.8 | F21: 0.01 | G21: =F21*G$4 -> 348827.58 | H21: 0.01 | I21: =H21*I$4 -> 416313.88
A22: Outflow | B22: =IF(C6=0,0,C22/C6) -> 1.05396 | C22: =SUMIF($D$3:$I$3,"Rp",$D22:$I22) -> 2.4921393e+08 | D22: =IF(E6=0,0,E22/E6) -> 1.0504151 | E22: =SUM(E8:E21)-IF(Rekap!$C$5="Ya",0,E13) -> 1.5329829e+08 | F22: =IF(G6=0,0,G22/G6) -> 1.0870562 | G22: =SUM(G8:G21)-IF(Rekap!$C$5="Ya",0,G13) -> 47703023 | H22: =IF(I6=0,0,I22/I6) -> 1.0339091 | I22: =SUM(I8:I21)-IF(Rekap!$C$5="Ya",0,I13) -> 48212614
A23: Profit | B23: =IF(C6=0,0,C23/C6) -> -0.053960018 | C23: =SUMIF($D$3:$I$3,"Rp",$D23:$I23) -> -12759106 | D23: =IF(E6=0,0,E23/E6) -> -0.050415107 | E23: =E6-E22 -> -7357614.9 | F23: =IF(G6=0,0,G23/G6) -> -0.087056178 | G23: =G6-G22 -> -3820265.2 | H23: =IF(I6=0,0,I23/I6) -> -0.033909055 | I23: =I6-I22 -> -1581226.3
A25: Catatan:
A26: • Sel biru/kuning = input. Nilai PO & % biaya diambil dari sheet project di file RAB Project TELCO.
A27: • Interest Bank = (% di Rekap!C4) × Dana Investor. Retensi masuk biaya/Dana Investor atau tidak diatur di Rekap!C5.
A28: • Pajak dihitung dari Nilai Proyek; Retensi & Cost Project dihitung dari Nilai PO Implementasi.
A29: • Kolom TOTAL menjumlah semua cluster otomatis.

Sheet Form EVANTAMA
A1: FORM PENGAJUAN DANA
A2: PT Indotek Buana Karya — Modal Kerja Proyek EVANTAMA 2026
A3: Sel kuning = diisi pemohon. Pilih cluster di "Nama Proyek"; angka budget otomatis ditarik dari sheet EVANTAMA.
A5: No. Pengajuan | C5: FPD/EVANTAMA/2026/10/001 | F5: Diajukan Oleh | H5: Pemohon Demo
A6: Tanggal Pengajuan | C6: 46308 | F6: Jabatan / Divisi | K6: helper (kolom ini boleh disembunyikan)
A7: Nama Proyek | C7: Cluster Sinagar Tasik | F7: Diajukan Kepada | H7: Investor | K7: =MATCH($C$7,EVANTAMA!$1:$1,0) -> 4
A8: Pemberi Kerja | C8: PT Evantama Network System | F8: Termin Pencairan Ke- | H8: 1
A9: Nilai Proyek (Rp) | C9: =INDEX(EVANTAMA!$6:$6,$K$7+1) -> 145940677 | F9: Periode Penggunaan | H9: Oktober
A11: RINCIAN KEBUTUHAN DANA
A12: No | B12: Pos Anggaran | C12: % Nilai Proyek | D12: Budget (Rp) | E12: % Dicairkan | F12: Diajukan Saat Ini (Rp) | G12: Sudah Dicairkan Sblm (Rp) | H12: Sisa Budget (Rp) | I12: Keterangan / Peruntukan
A13: A | B13: SUBCON, PERMIT & PAJAK
A14: 1 | B14: =TRIM(EVANTAMA!$A$8) -> Biaya Subcon | C14: =IF($C$9=0,0,D14/$C$9) -> 0.49484075 | D14: =INDEX(EVANTAMA!$8:$8,$K$7+1) -> 72217394 | E14: 1 | F14: =ROUND(D14*E14,0) -> 72217394 | G14: 0 | H14: =ROUND(D14,0)-G14-F14 -> 0 | I14: Pembayaran subcon
A15: 2 | B15: =TRIM(EVANTAMA!$A$9) -> Biaya Permit | C15: =IF($C$9=0,0,D15/$C$9) -> 0.25352767 | D15: =INDEX(EVANTAMA!$9:$9,$K$7+1) -> 37000000 | E15: 1 | F15: =ROUND(D15*E15,0) -> 37000000 | G15: 0 | H15: =ROUND(D15,0)-G15-F15 -> 0 | I15: Permit (pass-through)
A16: 3 | B16: =TRIM(EVANTAMA!$A$10) -> Ticket Internal | C16: =IF($C$9=0,0,D16/$C$9) -> 0 | D16: =INDEX(EVANTAMA!$10:$10,$K$7+1) -> 0 | E16: 1 | F16: =ROUND(D16*E16,0) -> 0 | G16: 0 | H16: =ROUND(D16,0)-G16-F16 -> 0 | I16: Tiket perjalanan
A17: 4 | B17: =TRIM(EVANTAMA!$A$12) -> Pajak | C17: =IF($C$9=0,0,D17/$C$9) -> 0.0265 | D17: =INDEX(EVANTAMA!$12:$12,$K$7+1) -> 3867427.9 | E17: 1 | F17: =ROUND(D17*E17,0) -> 3867428 | G17: 0 | H17: =ROUND(D17,0)-G17-F17 -> 0 | I17: Pajak atas nilai proyek
B18: Subtotal A | C18: =SUM(C14:C17) -> 0.77486842 | D18: =SUM(D14:D17) -> 1.1308482e+08 | F18: =SUM(F14:F17) -> 113084822 | G18: =SUM(G14:G17) -> 0 | H18: =SUM(H14:H17) -> 0
A19: B | B19: COST PROJECT
A20: 1 | B20: =TRIM(EVANTAMA!$A$15) -> Indirect Cost | C20: =IF($C$9=0,0,D20/$C$9) -> 0.014929447 | D20: =INDEX(EVANTAMA!$15:$15,$K$7+1) -> 2178813.5 | E20: 1 | F20: =ROUND(D20*E20,0) -> 2178814 | G20: 0 | H20: =ROUND(D20,0)-G20-F20 -> 0
A21: 2 | B21: =TRIM(EVANTAMA!$A$16) -> Direct Cost | C21: =IF($C$9=0,0,D21/$C$9) -> 0.029858893 | D21: =INDEX(EVANTAMA!$16:$16,$K$7+1) -> 4357627.1 | E21: 1 | F21: =ROUND(D21*E21,0) -> 4357627 | G21: 0 | H21: =ROUND(D21,0)-G21-F21 -> 0 | I21: Gaji/upah teknisi lapangan
A22: 3 | B22: =TRIM(EVANTAMA!$A$17) -> Operational Kantor | C22: =IF($C$9=0,0,D22/$C$9) -> 0.024520465 | D22: =INDEX(EVANTAMA!$17:$17,$K$7+1) -> 3578533.3 | E22: 1 | F22: =ROUND(D22*E22,0) -> 3578533 | G22: 0 | H22: =ROUND(D22,0)-G22-F22 -> 0
A23: 4 | B23: =TRIM(EVANTAMA!$A$18) -> Motor dan Mobil | C23: =IF($C$9=0,0,D23/$C$9) -> 0 | D23: =INDEX(EVANTAMA!$18:$18,$K$7+1) -> 0 | E23: 1 | F23: =ROUND(D23*E23,0) -> 0 | G23: 0 | H23: =ROUND(D23,0)-G23-F23 -> 0 | I23: Sewa/BBM kendaraan
A24: 5 | B24: =TRIM(EVANTAMA!$A$19) -> Homebase | C24: =IF($C$9=0,0,D24/$C$9) -> 0.013704198 | D24: =INDEX(EVANTAMA!$19:$19,$K$7+1) -> 2000000 | E24: 1 | F24: =ROUND(D24*E24,0) -> 2000000 | G24: 0 | H24: =ROUND(D24,0)-G24-F24 -> 0
A25: 6 | B25: =TRIM(EVANTAMA!$A$20) -> Allowance Kunjungan include ops permit | C25: =IF($C$9=0,0,D25/$C$9) -> 0.014929447 | D25: =INDEX(EVANTAMA!$20:$20,$K$7+1) -> 2178813.5 | E25: 1 | F25: =ROUND(D25*E25,0) -> 2178814 | G25: 0 | H25: =ROUND(D25,0)-G25-F25 -> 0 | I25: Termasuk ops permit
A26: 7 | B26: =TRIM(EVANTAMA!$A$21) -> Marketing cost | C26: =IF($C$9=0,0,D26/$C$9) -> 0.0074647233 | D26: =INDEX(EVANTAMA!$21:$21,$K$7+1) -> 1089406.8 | E26: 1 | F26: =ROUND(D26*E26,0) -> 1089407 | G26: 0 | H26: =ROUND(D26,0)-G26-F26 -> 0
B27: Subtotal B | C27: =SUM(C20:C26) -> 0.10540717 | D27: =SUM(D20:D26) -> 15383194 | F27: =SUM(F20:F26) -> 15383195 | G27: =SUM(G20:G26) -> 0 | H27: =SUM(H20:H26) -> 0
B28: TOTAL PENGAJUAN | C28: =C18+C27 -> 0.88027559 | D28: =D18+D27 -> 1.2846802e+08 | F28: =F18+F27 -> 128468017 | G28: =G18+G27 -> 0 | H28: =H18+H27 -> 0
A30: INFORMASI PENDUKUNG (tidak termasuk pengajuan) | K30: =ROUND(F28,0) -> 128468017
A31: ="Beban bunga dana investor ("&TEXT(Rekap!$C$4,"0%")&" × dana investor)" -> Beban bunga dana investor (10% × dana investor) | D31: =INDEX(EVANTAMA!$11:$11,$K$7+1) -> 13936208 | K31: =INT(K30/1000000000) -> 0
A32: Cadangan budget / retensi | D32: =INDEX(EVANTAMA!$13:$13,$K$7+1) -> 10894068 | K32: =INT(MOD(K30,1000000000)/1000000) -> 128
A33: Proyeksi profit cluster | D33: =INDEX(EVANTAMA!$23:$23,$K$7+1) -> -7357614.9 | K33: =INT(MOD(K30,1000000)/1000) -> 468
A34: Margin profit | D34: =INDEX(EVANTAMA!$23:$23,$K$7) -> -0.050415107 | K34: =MOD(K30,1000) -> 17
K35: =TRIM(IF(K31>0,VLOOKUP(K31,_terbilang!$A$1:$B$999,2,FALSE())&" milyar ","")&IF(K32>0,VLOOKUP(K32,_terbilang!$A$1:$B$999,2,FALSE())&" juta ","")&IF(K33=1,"seribu ",IF(K33>0,VLOOKUP(K33,_terbilang!$A$1:$B$999,2,FALSE())&" ribu ",""))&IF(K34>0,VLOOKUP(K34,_terbilang!$A$1:$B$999,2,FALSE()),""))&" rupiah" -> seratus dua puluh delapan juta empat ratus enam puluh delapan ribu tujuh belas rupiah
A36: Terbilang | C36: =IF(K30=0,"Nol rupiah",UPPER(LEFT(K35,1))&MID(K35,2,500)) -> Seratus dua puluh delapan juta empat ratus enam puluh delapan ribu tujuh belas rupiah
A37: Tujuan / Justifikasi Penggunaan Dana | C37: ="Modal kerja pelaksanaan pekerjaan FTTH "&C7&" untuk "&C8&"." -> Modal kerja pelaksanaan pekerjaan FTTH Cluster Sinagar Tasik untuk PT Evantama Network System.
A41: REKENING TUJUAN PENCAIRAN
A42: Nama Bank | C42: BCA
A43: No. Rekening | C43: 1234567890
A44: Atas Nama | C44: Pemohon Demo
A46: LAMPIRAN (beri tanda ✓)
A47: ✓ | B47: Proyeksi budget proyek (sheet EVANTAMA) | E47: ✓ | F47: ="PO / SPK dengan "&C8 -> PO / SPK dengan PT Evantama Network System
...

Sheet CCSI
A1: Proyeksi Project CCSI 2026 | B1: TOTAL CCSI | D1: Kalawiran Kakas Barat (Manado) | F1: Karondoran Langowan Timur (Manado) | H1: Padangsari RW 12 & 13 (Semarang)
D2: Site Manado · PO SND FTTHSWI-5-280926 · PO Implementasi FTTHSWI-6-280926 · biaya tetap site dialokasikan pro-rata nilai PO | F2: Site Manado · biaya tetap site dialokasikan pro-rata nilai PO | H2: Site Semarang · nilai PO belum dipisah per RW
B3: % | C3: Rp | D3: % | E3: Rp | F3: % | G3: Rp | H3: % | I3: Rp
A4: Nilai PO Implementasi | C4: =SUMIF($D$3:$I$3,"Rp",$D4:$I4) -> 136073359 | E4: 54419896 | G4: 38112632 | I4: 43540831
A5: Nilai PO Permit | C5: =SUMIF($D$3:$I$3,"Rp",$D5:$I5) -> 0 | E5: 0 | G5: 0 | I5: 0
A6: Nilai Proyek | C6: =SUMIF($D$3:$I$3,"Rp",$D6:$I6) -> 136073359 | E6: =E4+E5 -> 54419896 | G6: =G4+G5 -> 38112632 | I6: =I4+I5 -> 43540831
